Workbook

Sheet Statistical_Analysis
A1: station | B1: model | C1: experiment | D1: input | E1: input_length_tokens | F1: duration_seconds | G1: human_eval | H1: g_eval | I1: Difference
A2: d131 | B2: qwen | C2: Experiment 1 | D2: FI | E2: 3924 | F2: 48.55 | G2: ='d131 #1'!F3 -> 3.65 | H2: 3.5 | I2: =ABS(H2-G2) -> 0.15
A3: d131 | B3: qwen | C3: Experiment 1 | D3: P | E3: 8866 | F3: 60.65 | G3: ='d131 #1'!F4 -> 3.65 | H3: 3.65 | I3: =ABS(H3-G3) -> 0
A4: d131 | B4: qwen | C4: Experiment 1 | D4: FI + P | E4: 9097 | F4: 59.3 | G4: ='d131 #1'!F5 -> 3.3 | H4: 3.3 | I4: =ABS(H4-G4) -> 4.4408921e-16
A5: d131 | B5: deepseek | C5: Experiment 1 | D5: FI | E5: 2669 | F5: 66.6 | G5: ='d131 #1'!F6 -> 2.3 | H5: 2.5 | I5: =ABS(H5-G5) -> 0.2
A6: d131 | B6: deepseek | C6: Experiment 1 | D6: P | E6: 5601 | F6: 206.04 | G6: ='d131 #1'!F7 -> 3.65 | H6: 3.3 | I6: =ABS(H6-G6) -> 0.35
A7: d131 | B7: deepseek | C7: Experiment 1 | D7: FI + P | E7: 5743 | F7: 116.24 | G7: ='d131 #1'!F8 -> 3.4 | H7: 3.3 | I7: =ABS(H7-G7) -> 0.1
A8: d131 | B8: kimi | C8: Experiment 1 | D8: FI | E8: 2669 | F8: 24.46 | G8: ='d131 #1'!F9 -> 3.3 | H8: 3.3 | I8: =ABS(H8-G8) -> 4.4408921e-16
A9: d131 | B9: kimi | C9: Experiment 1 | D9: P | E9: 5566 | F9: 26.88 | G9: ='d131 #1'!F10 -> 3.25 | H9: 3.05 | I9: =ABS(H9-G9) -> 0.2
A10: d131 | B10: kimi | C10: Experiment 1 | D10: FI + P | E10: 5705 | F10: 24.95 | G10: ='d131 #1'!F11 -> 3.4 | H10: 3.3 | I10: =ABS(H10-G10) -> 0.1
A11: d393 | B11: qwen | C11: Experiment 1 | D11: FI | E11: 1927 | F11: 43.72 | G11: ='d393 #1'!F3 -> 4.35 | H11: 4.7 | I11: =ABS(H11-G11) -> 0.35
A12: d393 | B12: qwen | C12: Experiment 1 | D12: P | E12: 4317 | F12: 72.33 | G12: ='d393 #1'!F4 -> 4.2 | H12: 4.2 | I12: =ABS(H12-G12) -> 0
A13: d393 | B13: qwen | C13: Experiment 1 | D13: FI + P | E13: 4547 | F13: 57.89 | G13: ='d393 #1'!F5 -> 4.2 | H13: 4.1 | I13: =ABS(H13-G13) -> 0.1
A14: d393 | B14: deepseek | C14: Experiment 1 | D14: FI | E14: 1549 | F14: 97.2 | G14: ='d393 #1'!F6 -> 3.55 | H14: 3.8 | I14: =ABS(H14-G14) -> 0.25
A15: d393 | B15: deepseek | C15: Experiment 1 | D15: P | E15: 3064 | F15: 116.94 | G15: ='d393 #1'!F7 -> 3.9 | H15: 3.9 | I15: =ABS(H15-G15) -> 4.4408921e-16
A16: d393 | B16: deepseek | C16: Experiment 1 | D16: FI + P | E16: 3205 | F16: 121.81 | G16: ='d393 #1'!F8 -> 4.55 | H16: 4.6 | I16: =ABS(H16-G16) -> 0.05
A17: d393 | B17: kimi | C17: Experiment 1 | D17: FI | E17: 1550 | F17: 28.43 | G17: ='d393 #1'!F9 -> 4.1 | H17: 4.1 | I17: =ABS(H17-G17) -> 0
A18: d393 | B18: kimi | C18: Experiment 1 | D18: P | E18: 3034 | F18: 11.72 | G18: ='d393 #1'!F10 -> 3.95 | H18: 3.85 | I18: =ABS(H18-G18) -> 0.1
A19: d393 | B19: kimi | C19: Experiment 1 | D19: FI + P | E19: 3172 | F19: 27.51 | G19: ='d393 #1'!F11 -> 3.9 | H19: 3.8 | I19: =ABS(H19-G19) -> 0.1
A20: d1456 | B20: qwen | C20: Experiment 1 | D20: FI | E20: 3930 | F20: 60.04 | G20: ='d1456 #1'!F3 -> 4.1 | H20: 4.1 | I20: =ABS(H20-G20) -> 0
A21: d1456 | B21: qwen | C21: Experiment 1 | D21: P | E21: 8680 | F21: 55.56 | G21: ='d1456 #1'!F4 -> 4.2 | H21: 4.2 | I21: =ABS(H21-G21) -> 0
A22: d1456 | B22: qwen | C22: Experiment 1 | D22: FI + P | E22: 8914 | F22: 67 | G22: ='d1456 #1'!F5 -> 3.9 | H22: 4.15 | I22: =ABS(H22-G22) -> 0.25
A23: d1456 | B23: deepseek | C23: Experiment 1 | D23: FI | E23: 2668 | F23: 86.88 | G23: ='d1456 #1'!F6 -> 3.65 | H23: 3.9 | I23: =ABS(H23-G23) -> 0.25
A24: d1456 | B24: deepseek | C24: Experiment 1 | D24: P | E24: 5480 | F24: 92.22 | G24: ='d1456 #1'!F7 -> 3.45 | H24: 3.55 | I24: =ABS(H24-G24) -> 0.1
A25: d1456 | B25: deepseek | C25: Experiment 1 | D25: FI + P | E25: 5622 | F25: 82.61 | G25: ='d1456 #1'!F8 -> 3.8 | H25: 3.85 | I25: =ABS(H25-G25) -> 0.05
A26: d1456 | B26: kimi | C26: Experiment 1 | D26: FI | E26: 2670 | F26: 21.64 | G26: ='d1456 #1'!F9 -> 3.65 | H26: 3.55 | I26: =ABS(H26-G26) -> 0.1
A27: d1456 | B27: kimi | C27: Experiment 1 | D27: P | E27: 5450 | F27: 34.48 | G27: ='d1456 #1'!F10 -> 4.1 | H27: 4.1 | I27: =ABS(H27-G27) -> 0
A28: d1456 | B28: kimi | C28: Experiment 1 | D28: FI + P | E28: 5589 | F28: 46.06 | G28: ='d1456 #1'!F11 -> 3.85 | H28: 3.85 | I28: =ABS(H28-G28) -> 4.4408921e-16
A29: d3235 | B29: qwen | C29: Experiment 1 | D29: FI | E29: 3929 | F29: 52.85 | G29: ='d3235 #1'!F3 -> 3.75 | H29: 3.85 | I29: =ABS(H29-G29) -> 0.1
A30: d3235 | B30: qwen | C30: Experiment 1 | D30: P | E30: 8653 | F30: 63.44 | G30: ='d3235 #1'!F4 -> 4.2 | H30: 4.15 | I30: =ABS(H30-G30) -> 0.05
A31: d3235 | B31: qwen | C31: Experiment 1 | D31: FI + P | E31: 8888 | F31: 64.31 | G31: ='d3235 #1'!F5 -> 3.9 | H31: 3.8 | I31: =ABS(H31-G31) -> 0.1
A32: d3235 | B32: deepseek | C32: Experiment 1 | D32: FI | E32: 2670 | F32: 87.94 | G32: ='d3235 #1'!F6 -> 4 | H32: 4.25 | I32: =ABS(H32-G32) -> 0.25
A33: d3235 | B33: deepseek | C33: Experiment 1 | D33: P | E33: 5486 | F33: 50.65 | G33: ='d3235 #1'!F7 -> 3.8 | H33: 3.8 | I33: =ABS(H33-G33) -> 4.4408921e-16
A34: d3235 | B34: deepseek | C34: Experiment 1 | D34: FI + P | E34: 5628 | F34: 106.3 | G34: ='d3235 #1'!F8 -> 4.1 | H34: 4.1 | I34: =ABS(H34-G34) -> 0
A35: d3235 | B35: kimi | C35: Experiment 1 | D35: FI | E35: 2671 | F35: 37.19 | G35: ='d3235 #1'!F9 -> 4.55 | H35: 4.55 | I35: =ABS(H35-G35) -> 8.8817842e-16
A36: d3235 | B36: kimi | C36: Experiment 1 | D36: P | E36: 5456 | F36: 89.83 | G36: ='d3235 #1'!F10 -> 3.95 | H36: 3.85 | I36: =ABS(H36-G36) -> 0.1
A37: d3235 | B37: kimi | C37: Experiment 1 | D37: FI + P | E37: 5595 | F37: 50.28 | G37: ='d3235 #1'!F11 -> 3.4 | H37: 3.3 | I37: =ABS(H37-G37) -> 0.1
A38: d131 | B38: qwen | C38: Experiment 2 | D38: FI | E38: 4296 | F38: 64.09 | G38: ='d131 #2'!F3 -> 2.95 | H38: 2.85 | I38: =ABS(H38-G38) -> 0.1
A39: d131 | B39: qwen | C39: Experiment 2 | D39: P | E39: 12637 | F39: 59.2 | G39: ='d131 #2'!F4 -> 3.65 | H39: 3.65 | I39: =ABS(H39-G39) -> 4.4408921e-16
A40: d131 | B40: qwen | C40: Experiment 2 | D40: FI + P | E40: 14036 | F40: 65.96 | G40: ='d131 #2'!F5 -> 3.9 | H40: 4 | I40: =ABS(H40-G40) -> 0.1
...

Sheet d3235 #4
A1: Max Score: | B1: 5
F2: Weighted Score:
A3: gwen3.5 | FI | F3: =D12 -> 3.1
A4: Metric | B4: Weight | C4: Score [1,5] | D4: Weighted Score | F4: =D23 -> 3.2
A5: Is the explanation technically correct and based on the information provided without distorting the diagnostic information? (Soundness) | B5: 0.25 | C5: 3 | D5: =C5*B5 -> 0.75 | F5: =D34 -> 3.55
A6: Is the explanation readable, coherent and easy to understand for non-experts? (Fluency) | B6: 0.1 | C6: 5 | D6: =C6*B6 -> 0.5 | F6: =D45 -> 4.45
A7: Is the available information used for the reasoning? (Performance/Feature Importance/Combination) (Completeness) | B7: 0.1 | C7: 2 | D7: =C7*B7 -> 0.2 | F7: =D56 -> 4.2
A8: Does it answer why the specific device is behaving unusually or has a bad performance? (Completeness) | B8: 0.1 | C8: 3 | D8: =C8*B8 -> 0.3 | F8: =D67 -> 4.65
A9: Does it provide actionable insights that support the decision making? (Completeness) | B9: 0.1 | C9: 2 | D9: =C9*B9 -> 0.2
A10: Is there a coherent argumentation and reasoning provided for the interpretation based on the information provided? (Context-Awareness) | B10: 0.25 | C10: 3 | D10: =C10*B10 -> 0.75
A11: Does it avoid irrelevant and excessive information and is concise? (Length) | B11: 0.1 | C11: 4 | D11: =C11*B11 -> 0.4
B12: =SUM(B5:B11) -> 1 | D12: =SUM(D5:D11) -> 3.1
A14: gwen3.5 | P
A15: Metric | B15: Weight | C15: Score [1,5] | D15: Weighted Score
A16: Is the explanation technically correct and based on the information provided without distorting the diagnostic information? (Soundness) | B16: 0.25 | C16: 3 | D16: =C16*B16 -> 0.75
A17: Is the explanation readable, coherent and easy to understand for non-experts? (Fluency) | B17: 0.1 | C17: 4 | D17: =C17*B17 -> 0.4
A18: Is the available information used for the reasoning? (Performance/Feature Importance/Combination) (Completeness) | B18: 0.1 | C18: 3 | D18: =C18*B18 -> 0.3
A19: Does it answer why the specific device is behaving unusually or has a bad performance? (Completeness) | B19: 0.1 | C19: 3 | D19: =C19*B19 -> 0.3
A20: Does it provide actionable insights that support the decision making? (Completeness) | B20: 0.1 | C20: 3 | D20: =C20*B20 -> 0.3
A21: Is there a coherent argumentation and reasoning provided for the interpretation based on the information provided? (Context-Awareness) | B21: 0.25 | C21: 3 | D21: =C21*B21 -> 0.75
A22: Does it avoid irrelevant and excessive information and is concise? (Length) | B22: 0.1 | C22: 4 | D22: =C22*B22 -> 0.4
B23: =SUM(B16:B22) -> 1 | D23: =SUM(D16:D22) -> 3.2
A25: gwen3.5 | FI + P
A26: Metric | B26: Weight | C26: Score [1,5] | D26: Weighted Score
A27: Is the explanation technically correct and based on the information provided without distorting the diagnostic information? (Soundness) | B27: 0.25 | C27: 3 | D27: =C27*B27 -> 0.75
A28: Is the explanation readable, coherent and easy to understand for non-experts? (Fluency) | B28: 0.1 | C28: 5 | D28: =C28*B28 -> 0.5
A29: Is the available information used for the reasoning? (Performance/Feature Importance/Combination) (Completeness) | B29: 0.1 | C29: 3 | D29: =C29*B29 -> 0.3
A30: Does it answer why the specific device is behaving unusually or has a bad performance? (Completeness) | B30: 0.1 | C30: 3 | D30: =C30*B30 -> 0.3
A31: Does it provide actionable insights that support the decision making? (Completeness) | B31: 0.1 | C31: 3 | D31: =C31*B31 -> 0.3
A32: Is there a coherent argumentation and reasoning provided for the interpretation based on the information provided? (Context-Awareness) | B32: 0.25 | C32: 4 | D32: =C32*B32 -> 1
A33: Does it avoid irrelevant and excessive information and is concise? (Length) | B33: 0.1 | C33: 4 | D33: =C33*B33 -> 0.4
B34: =SUM(B27:B33) -> 1 | D34: =SUM(D27:D33) -> 3.55
A36: kimi-k2.5 | FI
A37: Metric | B37: Weight | C37: Score [1,5] | D37: Weighted Score
A38: Is the explanation technically correct and based on the information provided without distorting the diagnostic information? (Soundness) | B38: 0.25 | C38: 4 | D38: =C38*B38 -> 1
A39: Is the explanation readable, coherent and easy to understand for non-experts? (Fluency) | B39: 0.1 | C39: 5 | D39: =C39*B39 -> 0.5
A40: Is the available information used for the reasoning? (Performance/Feature Importance/Combination) (Completeness) | B40: 0.1 | C40: 4 | D40: =C40*B40 -> 0.4
A41: Does it answer why the specific device is behaving unusually or has a bad performance? (Completeness) | B41: 0.1 | C41: 4 | D41: =C41*B41 -> 0.4
A42: Does it provide actionable insights that support the decision making? (Completeness) | B42: 0.1 | C42: 5 | D42: =C42*B42 -> 0.5
A43: Is there a coherent argumentation and reasoning provided for the interpretation based on the information provided? (Context-Awareness) | B43: 0.25 | C43: 5 | D43: =C43*B43 -> 1.25
...

Sheet d131 #1
A1: Max Score: | B1: 5
F2: Weighted Score:
A3: gwen3.5 | FI | F3: =D12 -> 3.65
A4: Metric | B4: Weight | C4: Score [1,5] | D4: Weighted Score | F4: =D23 -> 3.65
A5: Is the explanation technically correct and based on the information provided without distorting the diagnostic information? (Soundness) | B5: 0.25 | C5: 4 | D5: =C5*B5 -> 1 | F5: =D34 -> 3.3
A6: Is the explanation readable, coherent and easy to understand for non-experts? (Fluency) | B6: 0.1 | C6: 5 | D6: =C6*B6 -> 0.5 | F6: =D45 -> 2.3
A7: Is the available information used for the reasoning? (Performance/Feature Importance/Combination) (Completeness) | B7: 0.1 | C7: 4 | D7: =C7*B7 -> 0.4 | F7: =D56 -> 3.65
A8: Does it answer why the specific device is behaving unusually or has a bad performance? (Completeness) | B8: 0.1 | C8: 3 | D8: =C8*B8 -> 0.3 | F8: =D67 -> 3.4
A9: Does it provide actionable insights that support the decision making? (Completeness) | B9: 0.1 | C9: 2 | D9: =C9*B9 -> 0.2 | F9: =D78 -> 3.3
A10: Is there a coherent argumentation and reasoning provided for the interpretation based on the information provided? (Context-Awareness) | B10: 0.25 | C10: 3 | D10: =C10*B10 -> 0.75 | F10: =D89 -> 3.25
A11: Does it avoid irrelevant and excessive information and is concise? (Length) | B11: 0.1 | C11: 5 | D11: =C11*B11 -> 0.5 | F11: =D100 -> 3.4
B12: =SUM(B5:B11) -> 1 | D12: =SUM(D5:D11) -> 3.65
A14: gwen3.5 | P
A15: Metric | B15: Weight | C15: Score [1,5] | D15: Weighted Score
A16: Is the explanation technically correct and based on the information provided without distorting the diagnostic information? (Soundness) | B16: 0.25 | C16: 3 | D16: =C16*B16 -> 0.75
A17: Is the explanation readable, coherent and easy to understand for non-experts? (Fluency) | B17: 0.1 | C17: 5 | D17: =C17*B17 -> 0.5
A18: Is the available information used for the reasoning? (Performance/Feature Importance/Combination) (Completeness) | B18: 0.1 | C18: 4 | D18: =C18*B18 -> 0.4
A19: Does it answer why the specific device is behaving unusually or has a bad performance? (Completeness) | B19: 0.1 | C19: 3 | D19: =C19*B19 -> 0.3
A20: Does it provide actionable insights that support the decision making? (Completeness) | B20: 0.1 | C20: 3 | D20: =C20*B20 -> 0.3
A21: Is there a coherent argumentation and reasoning provided for the interpretation based on the information provided? (Context-Awareness) | B21: 0.25 | C21: 4 | D21: =C21*B21 -> 1
A22: Does it avoid irrelevant and excessive information and is concise? (Length) | B22: 0.1 | C22: 4 | D22: =C22*B22 -> 0.4
B23: =SUM(B16:B22) -> 1 | D23: =SUM(D16:D22) -> 3.65
A25: gwen3.5 | FI + P
A26: Metric | B26: Weight | C26: Score [1,5] | D26: Weighted Score
A27: Is the explanation technically correct and based on the information provided without distorting the diagnostic information? (Soundness) | B27: 0.25 | C27: 3 | D27: =C27*B27 -> 0.75
A28: Is the explanation readable, coherent and easy to understand for non-experts? (Fluency) | B28: 0.1 | C28: 5 | D28: =C28*B28 -> 0.5
A29: Is the available information used for the reasoning? (Performance/Feature Importance/Combination) (Completeness) | B29: 0.1 | C29: 3 | D29: =C29*B29 -> 0.3
A30: Does it answer why the specific device is behaving unusually or has a bad performance? (Completeness) | B30: 0.1 | C30: 3 | D30: =C30*B30 -> 0.3
A31: Does it provide actionable insights that support the decision making? (Completeness) | B31: 0.1 | C31: 3 | D31: =C31*B31 -> 0.3
A32: Is there a coherent argumentation and reasoning provided for the interpretation based on the information provided? (Context-Awareness) | B32: 0.25 | C32: 3 | D32: =C32*B32 -> 0.75
A33: Does it avoid irrelevant and excessive information and is concise? (Length) | B33: 0.1 | C33: 4 | D33: =C33*B33 -> 0.4
B34: =SUM(B27:B33) -> 1 | D34: =SUM(D27:D33) -> 3.3
A36: deepseek-v3.2 | FI
A37: Metric | B37: Weight | C37: Score [1,5] | D37: Weighted Score
A38: Is the explanation technically correct and based on the information provided without distorting the diagnostic information? (Soundness) | B38: 0.25 | C38: 2 | D38: =C38*B38 -> 0.5
A39: Is the explanation readable, coherent and easy to understand for non-experts? (Fluency) | B39: 0.1 | C39: 3 | D39: =C39*B39 -> 0.3
A40: Is the available information used for the reasoning? (Performance/Feature Importance/Combination) (Completeness) | B40: 0.1 | C40: 2 | D40: =C40*B40 -> 0.2
A41: Does it answer why the specific device is behaving unusually or has a bad performance? (Completeness) | B41: 0.1 | C41: 2 | D41: =C41*B41 -> 0.2
A42: Does it provide actionable insights that support the decision making? (Completeness) | B42: 0.1 | C42: 3 | D42: =C42*B42 -> 0.3
A43: Is there a coherent argumentation and reasoning provided for the interpretation based on the information provided? (Context-Awareness) | B43: 0.25 | C43: 2 | D43: =C43*B43 -> 0.5
...

Sheet d393 #1
A1: Max Score: | B1: 5
F2: Weighted Score:
A3: gwen3.5 | FI | F3: =D12 -> 4.35
A4: Metric | B4: Weight | C4: Score [1,5] | D4: Weighted Score | F4: =D23 -> 4.2
A5: Is the explanation technically correct and based on the information provided without distorting the diagnostic information? (Soundness) | B5: 0.25 | C5: 4 | D5: =C5*B5 -> 1 | F5: =D34 -> 4.2
A6: Is the explanation readable, coherent and easy to understand for non-experts? (Fluency) | B6: 0.1 | C6: 5 | D6: =C6*B6 -> 0.5 | F6: =D45 -> 3.55
A7: Is the available information used for the reasoning? (Performance/Feature Importance/Combination) (Completeness) | B7: 0.1 | C7: 4 | D7: =C7*B7 -> 0.4 | F7: =D56 -> 3.9
A8: Does it answer why the specific device is behaving unusually or has a bad performance? (Completeness) | B8: 0.1 | C8: 4 | D8: =C8*B8 -> 0.4 | F8: =D67 -> 4.55
A9: Does it provide actionable insights that support the decision making? (Completeness) | B9: 0.1 | C9: 4 | D9: =C9*B9 -> 0.4 | F9: =D78 -> 4.1
A10: Is there a coherent argumentation and reasoning provided for the interpretation based on the information provided? (Context-Awareness) | B10: 0.25 | C10: 5 | D10: =C10*B10 -> 1.25 | F10: =D89 -> 3.95
A11: Does it avoid irrelevant and excessive information and is concise? (Length) | B11: 0.1 | C11: 4 | D11: =C11*B11 -> 0.4 | F11: =D100 -> 3.9
B12: =SUM(B5:B11) -> 1 | D12: =SUM(D5:D11) -> 4.35
A14: gwen3.5 | P
A15: Metric | B15: Weight | C15: Score [1,5] | D15: Weighted Score
A16: Is the explanation technically correct and based on the information provided without distorting the diagnostic information? (Soundness) | B16: 0.25 | C16: 4 | D16: =C16*B16 -> 1
A17: Is the explanation readable, coherent and easy to understand for non-experts? (Fluency) | B17: 0.1 | C17: 5 | D17: =C17*B17 -> 0.5
A18: Is the available information used for the reasoning? (Performance/Feature Importance/Combination) (Completeness) | B18: 0.1 | C18: 4 | D18: =C18*B18 -> 0.4
A19: Does it answer why the specific device is behaving unusually or has a bad performance? (Completeness) | B19: 0.1 | C19: 4 | D19: =C19*B19 -> 0.4
A20: Does it provide actionable insights that support the decision making? (Completeness) | B20: 0.1 | C20: 5 | D20: =C20*B20 -> 0.5
A21: Is there a coherent argumentation and reasoning provided for the interpretation based on the information provided? (Context-Awareness) | B21: 0.25 | C21: 4 | D21: =C21*B21 -> 1
A22: Does it avoid irrelevant and excessive information and is concise? (Length) | B22: 0.1 | C22: 4 | D22: =C22*B22 -> 0.4
B23: =SUM(B16:B22) -> 1 | D23: =SUM(D16:D22) -> 4.2
A25: gwen3.5 | FI + P
A26: Metric | B26: Weight | C26: Score [1,5] | D26: Weighted Score
A27: Is the explanation technically correct and based on the information provided without distorting the diagnostic information? (Soundness) | B27: 0.25 | C27: 4 | D27: =C27*B27 -> 1
A28: Is the explanation readable, coherent and easy to understand for non-experts? (Fluency) | B28: 0.1 | C28: 5 | D28: =C28*B28 -> 0.5
A29: Is the available information used for the reasoning? (Performance/Feature Importance/Combination) (Completeness) | B29: 0.1 | C29: 5 | D29: =C29*B29 -> 0.5
A30: Does it answer why the specific device is behaving unusually or has a bad performance? (Completeness) | B30: 0.1 | C30: 4 | D30: =C30*B30 -> 0.4
A31: Does it provide actionable insights that support the decision making? (Completeness) | B31: 0.1 | C31: 4 | D31: =C31*B31 -> 0.4
A32: Is there a coherent argumentation and reasoning provided for the interpretation based on the information provided? (Context-Awareness) | B32: 0.25 | C32: 4 | D32: =C32*B32 -> 1
A33: Does it avoid irrelevant and excessive information and is concise? (Length) | B33: 0.1 | C33: 4 | D33: =C33*B33 -> 0.4
B34: =SUM(B27:B33) -> 1 | D34: =SUM(D27:D33) -> 4.2
A36: deepseek-v3.2 | FI
A37: Metric | B37: Weight | C37: Score [1,5] | D37: Weighted Score
A38: Is the explanation technically correct and based on the information provided without distorting the diagnostic information? (Soundness) | B38: 0.25 | C38: 4 | D38: =C38*B38 -> 1
A39: Is the explanation readable, coherent and easy to understand for non-experts? (Fluency) | B39: 0.1 | C39: 5 | D39: =C39*B39 -> 0.5
A40: Is the available information used for the reasoning? (Performance/Feature Importance/Combination) (Completeness) | B40: 0.1 | C40: 2 | D40: =C40*B40 -> 0.2
A41: Does it answer why the specific device is behaving unusually or has a bad performance? (Completeness) | B41: 0.1 | C41: 4 | D41: =C41*B41 -> 0.4
A42: Does it provide actionable insights that support the decision making? (Completeness) | B42: 0.1 | C42: 3 | D42: =C42*B42 -> 0.3
A43: Is there a coherent argumentation and reasoning provided for the interpretation based on the information provided? (Context-Awareness) | B43: 0.25 | C43: 3 | D43: =C43*B43 -> 0.75
...

Sheet d1456 #1
A1: Max Score: | B1: 5
F2: Weighted Score:
A3: gwen3.5 | FI | F3: =D12 -> 4.1
A4: Metric | B4: Weight | C4: Score [1,5] | D4: Weighted Score | F4: =D23 -> 4.2
A5: Is the explanation technically correct and based on the information provided without distorting the diagnostic information? (Soundness) | B5: 0.25 | C5: 4 | D5: =C5*B5 -> 1 | F5: =D34 -> 3.9
A6: Is the explanation readable, coherent and easy to understand for non-experts? (Fluency) | B6: 0.1 | C6: 5 | D6: =C6*B6 -> 0.5 | F6: =D45 -> 3.65
A7: Is the available information used for the reasoning? (Performance/Feature Importance/Combination) (Completeness) | B7: 0.1 | C7: 4 | D7: =C7*B7 -> 0.4 | F7: =D56 -> 3.45
A8: Does it answer why the specific device is behaving unusually or has a bad performance? (Completeness) | B8: 0.1 | C8: 4 | D8: =C8*B8 -> 0.4 | F8: =D67 -> 3.8
A9: Does it provide actionable insights that support the decision making? (Completeness) | B9: 0.1 | C9: 4 | D9: =C9*B9 -> 0.4 | F9: =D78 -> 3.65
A10: Is there a coherent argumentation and reasoning provided for the interpretation based on the information provided? (Context-Awareness) | B10: 0.25 | C10: 4 | D10: =C10*B10 -> 1 | F10: =D89 -> 4.1
A11: Does it avoid irrelevant and excessive information and is concise? (Length) | B11: 0.1 | C11: 4 | D11: =C11*B11 -> 0.4 | F11: =D100 -> 3.85
B12: =SUM(B5:B11) -> 1 | D12: =SUM(D5:D11) -> 4.1
A14: gwen3.5 | P
A15: Metric | B15: Weight | C15: Score [1,5] | D15: Weighted Score
A16: Is the explanation technically correct and based on the information provided without distorting the diagnostic information? (Soundness) | B16: 0.25 | C16: 4 | D16: =C16*B16 -> 1
A17: Is the explanation readable, coherent and easy to understand for non-experts? (Fluency) | B17: 0.1 | C17: 5 | D17: =C17*B17 -> 0.5
A18: Is the available information used for the reasoning? (Performance/Feature Importance/Combination) (Completeness) | B18: 0.1 | C18: 5 | D18: =C18*B18 -> 0.5
A19: Does it answer why the specific device is behaving unusually or has a bad performance? (Completeness) | B19: 0.1 | C19: 5 | D19: =C19*B19 -> 0.5
A20: Does it provide actionable insights that support the decision making? (Completeness) | B20: 0.1 | C20: 3 | D20: =C20*B20 -> 0.3
A21: Is there a coherent argumentation and reasoning provided for the interpretation based on the information provided? (Context-Awareness) | B21: 0.25 | C21: 4 | D21: =C21*B21 -> 1
A22: Does it avoid irrelevant and excessive information and is concise? (Length) | B22: 0.1 | C22: 4 | D22: =C22*B22 -> 0.4
B23: =SUM(B16:B22) -> 1 | D23: =SUM(D16:D22) -> 4.2
A25: gwen3.5 | FI + P
A26: Metric | B26: Weight | C26: Score [1,5] | D26: Weighted Score
A27: Is the explanation technically correct and based on the information provided without distorting the diagnostic information? (Soundness) | B27: 0.25 | C27: 4 | D27: =C27*B27 -> 1
A28: Is the explanation readable, coherent and easy to understand for non-experts? (Fluency) | B28: 0.1 | C28: 5 | D28: =C28*B28 -> 0.5
A29: Is the available information used for the reasoning? (Performance/Feature Importance/Combination) (Completeness) | B29: 0.1 | C29: 4 | D29: =C29*B29 -> 0.4
A30: Does it answer why the specific device is behaving unusually or has a bad performance? (Completeness) | B30: 0.1 | C30: 3 | D30: =C30*B30 -> 0.3
A31: Does it provide actionable insights that support the decision making? (Completeness) | B31: 0.1 | C31: 3 | D31: =C31*B31 -> 0.3
A32: Is there a coherent argumentation and reasoning provided for the interpretation based on the information provided? (Context-Awareness) | B32: 0.25 | C32: 4 | D32: =C32*B32 -> 1
A33: Does it avoid irrelevant and excessive information and is concise? (Length) | B33: 0.1 | C33: 4 | D33: =C33*B33 -> 0.4
B34: =SUM(B27:B33) -> 1 | D34: =SUM(D27:D33) -> 3.9
A36: deepseek-v3.2 | FI
A37: Metric | B37: Weight | C37: Score [1,5] | D37: Weighted Score
A38: Is the explanation technically correct and based on the information provided without distorting the diagnostic information? (Soundness) | B38: 0.25 | C38: 3 | D38: =C38*B38 -> 0.75
A39: Is the explanation readable, coherent and easy to understand for non-experts? (Fluency) | B39: 0.1 | C39: 5 | D39: =C39*B39 -> 0.5
A40: Is the available information used for the reasoning? (Performance/Feature Importance/Combination) (Completeness) | B40: 0.1 | C40: 3 | D40: =C40*B40 -> 0.3
A41: Does it answer why the specific device is behaving unusually or has a bad performance? (Completeness) | B41: 0.1 | C41: 3 | D41: =C41*B41 -> 0.3
A42: Does it provide actionable insights that support the decision making? (Completeness) | B42: 0.1 | C42: 3 | D42: =C42*B42 -> 0.3
A43: Is there a coherent argumentation and reasoning provided for the interpretation based on the information provided? (Context-Awareness) | B43: 0.25 | C43: 4 | D43: =C43*B43 -> 1
...

Sheet d3235 #1
A1: Max Score: | B1: 5
F2: Weighted Score:
A3: gwen3.5 | FI | F3: =D12 -> 3.75
A4: Metric | B4: Weight | C4: Score [1,5] | D4: Weighted Score | F4: =D23 -> 4.2
A5: Is the explanation technically correct and based on the information provided without distorting the diagnostic information? (Soundness) | B5: 0.25 | C5: 3 | D5: =C5*B5 -> 0.75 | F5: =D34 -> 3.9
A6: Is the explanation readable, coherent and easy to understand for non-experts? (Fluency) | B6: 0.1 | C6: 5 | D6: =C6*B6 -> 0.5 | F6: =D45 -> 4
A7: Is the available information used for the reasoning? (Performance/Feature Importance/Combination) (Completeness) | B7: 0.1 | C7: 4 | D7: =C7*B7 -> 0.4 | F7: =D56 -> 3.8
A8: Does it answer why the specific device is behaving unusually or has a bad performance? (Completeness) | B8: 0.1 | C8: 4 | D8: =C8*B8 -> 0.4 | F8: =D67 -> 4.1
A9: Does it provide actionable insights that support the decision making? (Completeness) | B9: 0.1 | C9: 2 | D9: =C9*B9 -> 0.2 | F9: =D78 -> 4.55
A10: Is there a coherent argumentation and reasoning provided for the interpretation based on the information provided? (Context-Awareness) | B10: 0.25 | C10: 4 | D10: =C10*B10 -> 1 | F10: =D89 -> 3.95
A11: Does it avoid irrelevant and excessive information and is concise? (Length) | B11: 0.1 | C11: 5 | D11: =C11*B11 -> 0.5 | F11: =D100 -> 3.4
B12: =SUM(B5:B11) -> 1 | D12: =SUM(D5:D11) -> 3.75
A14: gwen3.5 | P
A15: Metric | B15: Weight | C15: Score [1,5] | D15: Weighted Score
A16: Is the explanation technically correct and based on the information provided without distorting the diagnostic information? (Soundness) | B16: 0.25 | C16: 4 | D16: =C16*B16 -> 1
A17: Is the explanation readable, coherent and easy to understand for non-experts? (Fluency) | B17: 0.1 | C17: 5 | D17: =C17*B17 -> 0.5
A18: Is the available information used for the reasoning? (Performance/Feature Importance/Combination) (Completeness) | B18: 0.1 | C18: 4 | D18: =C18*B18 -> 0.4
A19: Does it answer why the specific device is behaving unusually or has a bad performance? (Completeness) | B19: 0.1 | C19: 5 | D19: =C19*B19 -> 0.5
A20: Does it provide actionable insights that support the decision making? (Completeness) | B20: 0.1 | C20: 4 | D20: =C20*B20 -> 0.4
A21: Is there a coherent argumentation and reasoning provided for the interpretation based on the information provided? (Context-Awareness) | B21: 0.25 | C21: 4 | D21: =C21*B21 -> 1
A22: Does it avoid irrelevant and excessive information and is concise? (Length) | B22: 0.1 | C22: 4 | D22: =C22*B22 -> 0.4
B23: =SUM(B16:B22) -> 1 | D23: =SUM(D16:D22) -> 4.2
A25: gwen3.5 | FI + P
A26: Metric | B26: Weight | C26: Score [1,5] | D26: Weighted Score
A27: Is the explanation technically correct and based on the information provided without distorting the diagnostic information? (Soundness) | B27: 0.25 | C27: 4 | D27: =C27*B27 -> 1
A28: Is the explanation readable, coherent and easy to understand for non-experts? (Fluency) | B28: 0.1 | C28: 5 | D28: =C28*B28 -> 0.5
A29: Is the available information used for the reasoning? (Performance/Feature Importance/Combination) (Completeness) | B29: 0.1 | C29: 3 | D29: =C29*B29 -> 0.3
A30: Does it answer why the specific device is behaving unusually or has a bad performance? (Completeness) | B30: 0.1 | C30: 3 | D30: =C30*B30 -> 0.3
A31: Does it provide actionable insights that support the decision making? (Completeness) | B31: 0.1 | C31: 4 | D31: =C31*B31 -> 0.4
A32: Is there a coherent argumentation and reasoning provided for the interpretation based on the information provided? (Context-Awareness) | B32: 0.25 | C32: 4 | D32: =C32*B32 -> 1
A33: Does it avoid irrelevant and excessive information and is concise? (Length) | B33: 0.1 | C33: 4 | D33: =C33*B33 -> 0.4
B34: =SUM(B27:B33) -> 1 | D34: =SUM(D27:D33) -> 3.9
A36: deepseek-v3.2 | FI
A37: Metric | B37: Weight | C37: Score [1,5] | D37: Weighted Score
A38: Is the explanation technically correct and based on the information provided without distorting the diagnostic information? (Soundness) | B38: 0.25 | C38: 4 | D38: =C38*B38 -> 1
A39: Is the explanation readable, coherent and easy to understand for non-experts? (Fluency) | B39: 0.1 | C39: 5 | D39: =C39*B39 -> 0.5
A40: Is the available information used for the reasoning? (Performance/Feature Importance/Combination) (Completeness) | B40: 0.1 | C40: 4 | D40: =C40*B40 -> 0.4
A41: Does it answer why the specific device is behaving unusually or has a bad performance? (Completeness) | B41: 0.1 | C41: 4 | D41: =C41*B41 -> 0.4
A42: Does it provide actionable insights that support the decision making? (Completeness) | B42: 0.1 | C42: 3 | D42: =C42*B42 -> 0.3
A43: Is there a coherent argumentation and reasoning provided for the interpretation based on the information provided? (Context-Awareness) | B43: 0.25 | C43: 4 | D43: =C43*B43 -> 1
...

Sheet d131 #2
A1: Max Score: | B1: 5
F2: Weighted Score:
A3: gwen3.5 | FI | F3: =D12 -> 2.95
A4: Metric | B4: Weight | C4: Score [1,5] | D4: Weighted Score | F4: =D23 -> 3.65
A5: Is the explanation technically correct and based on the information provided without distorting the diagnostic information? (Soundness) | B5: 0.25 | C5: 2 | D5: =C5*B5 -> 0.5 | F5: =D34 -> 3.9
A6: Is the explanation readable, coherent and easy to understand for non-experts? (Fluency) | B6: 0.1 | C6: 4 | D6: =C6*B6 -> 0.4 | F6: =D45 -> 4
A7: Is the available information used for the reasoning? (Performance/Feature Importance/Combination) (Completeness) | B7: 0.1 | C7: 3 | D7: =C7*B7 -> 0.3 | F7: =D56 -> 4.1
A8: Does it answer why the specific device is behaving unusually or has a bad performance? (Completeness) | B8: 0.1 | C8: 3 | D8: =C8*B8 -> 0.3 | F8: =D67 -> 4.2
A9: Does it provide actionable insights that support the decision making? (Completeness) | B9: 0.1 | C9: 3 | D9: =C9*B9 -> 0.3 | F9: =D78 -> 3.65
A10: Is there a coherent argumentation and reasoning provided for the interpretation based on the information provided? (Context-Awareness) | B10: 0.25 | C10: 3 | D10: =C10*B10 -> 0.75 | F10: =D89 -> 4.3
A11: Does it avoid irrelevant and excessive information and is concise? (Length) | B11: 0.1 | C11: 4 | D11: =C11*B11 -> 0.4 | F11: =D100 -> 3.55
B12: =SUM(B5:B11) -> 1 | D12: =SUM(D5:D11) -> 2.95
A14: gwen3.5 | P
A15: Metric | B15: Weight | C15: Score [1,5] | D15: Weighted Score
A16: Is the explanation technically correct and based on the information provided without distorting the diagnostic information? (Soundness) | B16: 0.25 | C16: 3 | D16: =C16*B16 -> 0.75
A17: Is the explanation readable, coherent and easy to understand for non-experts? (Fluency) | B17: 0.1 | C17: 5 | D17: =C17*B17 -> 0.5
A18: Is the available information used for the reasoning? (Performance/Feature Importance/Combination) (Completeness) | B18: 0.1 | C18: 3 | D18: =C18*B18 -> 0.3
A19: Does it answer why the specific device is behaving unusually or has a bad performance? (Completeness) | B19: 0.1 | C19: 3 | D19: =C19*B19 -> 0.3
A20: Does it provide actionable insights that support the decision making? (Completeness) | B20: 0.1 | C20: 3 | D20: =C20*B20 -> 0.3
A21: Is there a coherent argumentation and reasoning provided for the interpretation based on the information provided? (Context-Awareness) | B21: 0.25 | C21: 4 | D21: =C21*B21 -> 1
A22: Does it avoid irrelevant and excessive information and is concise? (Length) | B22: 0.1 | C22: 5 | D22: =C22*B22 -> 0.5
B23: =SUM(B16:B22) -> 1 | D23: =SUM(D16:D22) -> 3.65
A25: gwen3.5 | FI + P
A26: Metric | B26: Weight | C26: Score [1,5] | D26: Weighted Score
A27: Is the explanation technically correct and based on the information provided without distorting the diagnostic information? (Soundness) | B27: 0.25 | C27: 4 | D27: =C27*B27 -> 1
A28: Is the explanation readable, coherent and easy to understand for non-experts? (Fluency) | B28: 0.1 | C28: 5 | D28: =C28*B28 -> 0.5
A29: Is the available information used for the reasoning? (Performance/Feature Importance/Combination) (Completeness) | B29: 0.1 | C29: 3 | D29: =C29*B29 -> 0.3
A30: Does it answer why the specific device is behaving unusually or has a bad performance? (Completeness) | B30: 0.1 | C30: 3 | D30: =C30*B30 -> 0.3
A31: Does it provide actionable insights that support the decision making? (Completeness) | B31: 0.1 | C31: 4 | D31: =C31*B31 -> 0.4
A32: Is there a coherent argumentation and reasoning provided for the interpretation based on the information provided? (Context-Awareness) | B32: 0.25 | C32: 4 | D32: =C32*B32 -> 1
A33: Does it avoid irrelevant and excessive information and is concise? (Length) | B33: 0.1 | C33: 4 | D33: =C33*B33 -> 0.4
B34: =SUM(B27:B33) -> 1 | D34: =SUM(D27:D33) -> 3.9
A36: deepseek-v3.2 | FI
A37: Metric | B37: Weight | C37: Score [1,5] | D37: Weighted Score
A38: Is the explanation technically correct and based on the information provided without distorting the diagnostic information? (Soundness) | B38: 0.25 | C38: 4 | D38: =C38*B38 -> 1
A39: Is the explanation readable, coherent and easy to understand for non-experts? (Fluency) | B39: 0.1 | C39: 5 | D39: =C39*B39 -> 0.5
A40: Is the available information used for the reasoning? (Performance/Feature Importance/Combination) (Completeness) | B40: 0.1 | C40: 3 | D40: =C40*B40 -> 0.3
A41: Does it answer why the specific device is behaving unusually or has a bad performance? (Completeness) | B41: 0.1 | C41: 4 | D41: =C41*B41 -> 0.4
A42: Does it provide actionable insights that support the decision making? (Completeness) | B42: 0.1 | C42: 3 | D42: =C42*B42 -> 0.3
A43: Is there a coherent argumentation and reasoning provided for the interpretation based on the information provided? (Context-Awareness) | B43: 0.25 | C43: 4 | D43: =C43*B43 -> 1
...

Sheet d393 #2
A1: Max Score: | B1: 5
F2: Weighted Score:
A3: gwen3.5 | FI | F3: =D12 -> 4.1
A4: Metric | B4: Weight | C4: Score [1,5] | D4: Weighted Score | F4: =D23 -> 4.1
A5: Is the explanation technically correct and based on the information provided without distorting the diagnostic information? (Soundness) | B5: 0.25 | C5: 4 | D5: =C5*B5 -> 1 | F5: =D34 -> 4.2
A6: Is the explanation readable, coherent and easy to understand for non-experts? (Fluency) | B6: 0.1 | C6: 5 | D6: =C6*B6 -> 0.5 | F6: =D45 -> 4.1
A7: Is the available information used for the reasoning? (Performance/Feature Importance/Combination) (Completeness) | B7: 0.1 | C7: 4 | D7: =C7*B7 -> 0.4 | F7: =D56 -> 3.9
A8: Does it answer why the specific device is behaving unusually or has a bad performance? (Completeness) | B8: 0.1 | C8: 4 | D8: =C8*B8 -> 0.4 | F8: =D67 -> 4.7
A9: Does it provide actionable insights that support the decision making? (Completeness) | B9: 0.1 | C9: 3 | D9: =C9*B9 -> 0.3 | F9: =D78 -> 4.55
A10: Is there a coherent argumentation and reasoning provided for the interpretation based on the information provided? (Context-Awareness) | B10: 0.25 | C10: 4 | D10: =C10*B10 -> 1 | F10: =D89 -> 3.85
A11: Does it avoid irrelevant and excessive information and is concise? (Length) | B11: 0.1 | C11: 5 | D11: =C11*B11 -> 0.5 | F11: =D100 -> 4.4
B12: =SUM(B5:B11) -> 1 | D12: =SUM(D5:D11) -> 4.1
A14: gwen3.5 | P
A15: Metric | B15: Weight | C15: Score [1,5] | D15: Weighted Score
A16: Is the explanation technically correct and based on the information provided without distorting the diagnostic information? (Soundness) | B16: 0.25 | C16: 4 | D16: =C16*B16 -> 1
A17: Is the explanation readable, coherent and easy to understand for non-experts? (Fluency) | B17: 0.1 | C17: 5 | D17: =C17*B17 -> 0.5
A18: Is the available information used for the reasoning? (Performance/Feature Importance/Combination) (Completeness) | B18: 0.1 | C18: 4 | D18: =C18*B18 -> 0.4
A19: Does it answer why the specific device is behaving unusually or has a bad performance? (Completeness) | B19: 0.1 | C19: 4 | D19: =C19*B19 -> 0.4
A20: Does it provide actionable insights that support the decision making? (Completeness) | B20: 0.1 | C20: 3 | D20: =C20*B20 -> 0.3
A21: Is there a coherent argumentation and reasoning provided for the interpretation based on the information provided? (Context-Awareness) | B21: 0.25 | C21: 4 | D21: =C21*B21 -> 1
A22: Does it avoid irrelevant and excessive information and is concise? (Length) | B22: 0.1 | C22: 5 | D22: =C22*B22 -> 0.5
B23: =SUM(B16:B22) -> 1 | D23: =SUM(D16:D22) -> 4.1
A25: gwen3.5 | FI + P
A26: Metric | B26: Weight | C26: Score [1,5] | D26: Weighted Score
A27: Is the explanation technically correct and based on the information provided without distorting the diagnostic information? (Soundness) | B27: 0.25 | C27: 4 | D27: =C27*B27 -> 1
A28: Is the explanation readable, coherent and easy to understand for non-experts? (Fluency) | B28: 0.1 | C28: 5 | D28: =C28*B28 -> 0.5
A29: Is the available information used for the reasoning? (Performance/Feature Importance/Combination) (Completeness) | B29: 0.1 | C29: 4 | D29: =C29*B29 -> 0.4
A30: Does it answer why the specific device is behaving unusually or has a bad performance? (Completeness) | B30: 0.1 | C30: 4 | D30: =C30*B30 -> 0.4
A31: Does it provide actionable insights that support the decision making? (Completeness) | B31: 0.1 | C31: 4 | D31: =C31*B31 -> 0.4
A32: Is there a coherent argumentation and reasoning provided for the interpretation based on the information provided? (Context-Awareness) | B32: 0.25 | C32: 4 | D32: =C32*B32 -> 1
A33: Does it avoid irrelevant and excessive information and is concise? (Length) | B33: 0.1 | C33: 5 | D33: =C33*B33 -> 0.5
B34: =SUM(B27:B33) -> 1 | D34: =SUM(D27:D33) -> 4.2
A36: deepseek-v3.2 | FI
A37: Metric | B37: Weight | C37: Score [1,5] | D37: Weighted Score
A38: Is the explanation technically correct and based on the information provided without distorting the diagnostic information? (Soundness) | B38: 0.25 | C38: 4 | D38: =C38*B38 -> 1
A39: Is the explanation readable, coherent and easy to understand for non-experts? (Fluency) | B39: 0.1 | C39: 5 | D39: =C39*B39 -> 0.5
A40: Is the available information used for the reasoning? (Performance/Feature Importance/Combination) (Completeness) | B40: 0.1 | C40: 4 | D40: =C40*B40 -> 0.4
A41: Does it answer why the specific device is behaving unusually or has a bad performance? (Completeness) | B41: 0.1 | C41: 4 | D41: =C41*B41 -> 0.4
A42: Does it provide actionable insights that support the decision making? (Completeness) | B42: 0.1 | C42: 4 | D42: =C42*B42 -> 0.4
A43: Is there a coherent argumentation and reasoning provided for the interpretation based on the information provided? (Context-Awareness) | B43: 0.25 | C43: 4 | D43: =C43*B43 -> 1
...

Sheet d1456 #2
A1: Max Score: | B1: 5
F2: Weighted Score:
A3: gwen3.5 | FI | F3: =D12 -> 3.9
A4: Metric | B4: Weight | C4: Score [1,5] | D4: Weighted Score | F4: =D23 -> 4.1
A5: Is the explanation technically correct and based on the information provided without distorting the diagnostic information? (Soundness) | B5: 0.25 | C5: 4 | D5: =C5*B5 -> 1 | F5: =D34 -> 3.9
A6: Is the explanation readable, coherent and easy to understand for non-experts? (Fluency) | B6: 0.1 | C6: 5 | D6: =C6*B6 -> 0.5 | F6: =D45 -> 4
A7: Is the available information used for the reasoning? (Performance/Feature Importance/Combination) (Completeness) | B7: 0.1 | C7: 3 | D7: =C7*B7 -> 0.3 | F7: =D56 -> 3.2
A8: Does it answer why the specific device is behaving unusually or has a bad performance? (Completeness) | B8: 0.1 | C8: 3 | D8: =C8*B8 -> 0.3 | F8: =D67 -> 4.2
A9: Does it provide actionable insights that support the decision making? (Completeness) | B9: 0.1 | C9: 3 | D9: =C9*B9 -> 0.3 | F9: =D78 -> 3.65
A10: Is there a coherent argumentation and reasoning provided for the interpretation based on the information provided? (Context-Awareness) | B10: 0.25 | C10: 4 | D10: =C10*B10 -> 1 | F10: =D89 -> 4.1
A11: Does it avoid irrelevant and excessive information and is concise? (Length) | B11: 0.1 | C11: 5 | D11: =C11*B11 -> 0.5 | F11: =D100 -> 3.65
B12: =SUM(B5:B11) -> 1 | D12: =SUM(D5:D11) -> 3.9
A14: gwen3.5 | P
A15: Metric | B15: Weight | C15: Score [1,5] | D15: Weighted Score
A16: Is the explanation technically correct and based on the information provided without distorting the diagnostic information? (Soundness) | B16: 0.25 | C16: 4 | D16: =C16*B16 -> 1
A17: Is the explanation readable, coherent and easy to understand for non-experts? (Fluency) | B17: 0.1 | C17: 5 | D17: =C17*B17 -> 0.5
A18: Is the available information used for the reasoning? (Performance/Feature Importance/Combination) (Completeness) | B18: 0.1 | C18: 3 | D18: =C18*B18 -> 0.3
A19: Does it answer why the specific device is behaving unusually or has a bad performance? (Completeness) | B19: 0.1 | C19: 4 | D19: =C19*B19 -> 0.4
A20: Does it provide actionable insights that support the decision making? (Completeness) | B20: 0.1 | C20: 4 | D20: =C20*B20 -> 0.4
A21: Is there a coherent argumentation and reasoning provided for the interpretation based on the information provided? (Context-Awareness) | B21: 0.25 | C21: 4 | D21: =C21*B21 -> 1
A22: Does it avoid irrelevant and excessive information and is concise? (Length) | B22: 0.1 | C22: 5 | D22: =C22*B22 -> 0.5
B23: =SUM(B16:B22) -> 1 | D23: =SUM(D16:D22) -> 4.1
A25: gwen3.5 | FI + P
A26: Metric | B26: Weight | C26: Score [1,5] | D26: Weighted Score
A27: Is the explanation technically correct and based on the information provided without distorting the diagnostic information? (Soundness) | B27: 0.25 | C27: 4 | D27: =C27*B27 -> 1
A28: Is the explanation readable, coherent and easy to understand for non-experts? (Fluency) | B28: 0.1 | C28: 5 | D28: =C28*B28 -> 0.5
A29: Is the available information used for the reasoning? (Performance/Feature Importance/Combination) (Completeness) | B29: 0.1 | C29: 3 | D29: =C29*B29 -> 0.3
A30: Does it answer why the specific device is behaving unusually or has a bad performance? (Completeness) | B30: 0.1 | C30: 4 | D30: =C30*B30 -> 0.4
A31: Does it provide actionable insights that support the decision making? (Completeness) | B31: 0.1 | C31: 2 | D31: =C31*B31 -> 0.2
A32: Is there a coherent argumentation and reasoning provided for the interpretation based on the information provided? (Context-Awareness) | B32: 0.25 | C32: 4 | D32: =C32*B32 -> 1
A33: Does it avoid irrelevant and excessive information and is concise? (Length) | B33: 0.1 | C33: 5 | D33: =C33*B33 -> 0.5
B34: =SUM(B27:B33) -> 1 | D34: =SUM(D27:D33) -> 3.9
A36: deepseek-v3.2 | FI
A37: Metric | B37: Weight | C37: Score [1,5] | D37: Weighted Score
A38: Is the explanation technically correct and based on the information provided without distorting the diagnostic information? (Soundness) | B38: 0.25 | C38: 4 | D38: =C38*B38 -> 1
A39: Is the explanation readable, coherent and easy to understand for non-experts? (Fluency) | B39: 0.1 | C39: 5 | D39: =C39*B39 -> 0.5
A40: Is the available information used for the reasoning? (Performance/Feature Importance/Combination) (Completeness) | B40: 0.1 | C40: 3 | D40: =C40*B40 -> 0.3
A41: Does it answer why the specific device is behaving unusually or has a bad performance? (Completeness) | B41: 0.1 | C41: 3 | D41: =C41*B41 -> 0.3
A42: Does it provide actionable insights that support the decision making? (Completeness) | B42: 0.1 | C42: 4 | D42: =C42*B42 -> 0.4
A43: Is there a coherent argumentation and reasoning provided for the interpretation based on the information provided? (Context-Awareness) | B43: 0.25 | C43: 4 | D43: =C43*B43 -> 1
...

Sheet d3235 #2
A1: Max Score: | B1: 5
F2: Weighted Score:
A3: gwen3.5 | FI | F3: =D12 -> 4.1
A4: Metric | B4: Weight | C4: Score [1,5] | D4: Weighted Score | F4: =D23 -> 3.65
A5: Is the explanation technically correct and based on the information provided without distorting the diagnostic information? (Soundness) | B5: 0.25 | C5: 4 | D5: =C5*B5 -> 1 | F5: =D34 -> 3.75
A6: Is the explanation readable, coherent and easy to understand for non-experts? (Fluency) | B6: 0.1 | C6: 5 | D6: =C6*B6 -> 0.5 | F6: =D45 -> 3.3
A7: Is the available information used for the reasoning? (Performance/Feature Importance/Combination) (Completeness) | B7: 0.1 | C7: 4 | D7: =C7*B7 -> 0.4 | F7: =D56 -> 4.1
A8: Does it answer why the specific device is behaving unusually or has a bad performance? (Completeness) | B8: 0.1 | C8: 4 | D8: =C8*B8 -> 0.4 | F8: =D67 -> 4
A9: Does it provide actionable insights that support the decision making? (Completeness) | B9: 0.1 | C9: 4 | D9: =C9*B9 -> 0.4 | F9: =D78 -> 4.9
A10: Is there a coherent argumentation and reasoning provided for the interpretation based on the information provided? (Context-Awareness) | B10: 0.25 | C10: 4 | D10: =C10*B10 -> 1 | F10: =D89 -> 4.1
A11: Does it avoid irrelevant and excessive information and is concise? (Length) | B11: 0.1 | C11: 4 | D11: =C11*B11 -> 0.4 | F11: =D100 -> 4.65
B12: =SUM(B5:B11) -> 1 | D12: =SUM(D5:D11) -> 4.1
A14: gwen3.5 | P
A15: Metric | B15: Weight | C15: Score [1,5] | D15: Weighted Score
A16: Is the explanation technically correct and based on the information provided without distorting the diagnostic information? (Soundness) | B16: 0.25 | C16: 3 | D16: =C16*B16 -> 0.75
A17: Is the explanation readable, coherent and easy to understand for non-experts? (Fluency) | B17: 0.1 | C17: 5 | D17: =C17*B17 -> 0.5
A18: Is the available information used for the reasoning? (Performance/Feature Importance/Combination) (Completeness) | B18: 0.1 | C18: 3 | D18: =C18*B18 -> 0.3
A19: Does it answer why the specific device is behaving unusually or has a bad performance? (Completeness) | B19: 0.1 | C19: 3 | D19: =C19*B19 -> 0.3
A20: Does it provide actionable insights that support the decision making? (Completeness) | B20: 0.1 | C20: 4 | D20: =C20*B20 -> 0.4
A21: Is there a coherent argumentation and reasoning provided for the interpretation based on the information provided? (Context-Awareness) | B21: 0.25 | C21: 4 | D21: =C21*B21 -> 1
A22: Does it avoid irrelevant and excessive information and is concise? (Length) | B22: 0.1 | C22: 4 | D22: =C22*B22 -> 0.4
B23: =SUM(B16:B22) -> 1 | D23: =SUM(D16:D22) -> 3.65
A25: gwen3.5 | FI + P
A26: Metric | B26: Weight | C26: Score [1,5] | D26: Weighted Score
A27: Is the explanation technically correct and based on the information provided without distorting the diagnostic information? (Soundness) | B27: 0.25 | C27: 3 | D27: =C27*B27 -> 0.75
A28: Is the explanation readable, coherent and easy to understand for non-experts? (Fluency) | B28: 0.1 | C28: 5 | D28: =C28*B28 -> 0.5
A29: Is the available information used for the reasoning? (Performance/Feature Importance/Combination) (Completeness) | B29: 0.1 | C29: 4 | D29: =C29*B29 -> 0.4
A30: Does it answer why the specific device is behaving unusually or has a bad performance? (Completeness) | B30: 0.1 | C30: 4 | D30: =C30*B30 -> 0.4
A31: Does it provide actionable insights that support the decision making? (Completeness) | B31: 0.1 | C31: 4 | D31: =C31*B31 -> 0.4
A32: Is there a coherent argumentation and reasoning provided for the interpretation based on the information provided? (Context-Awareness) | B32: 0.25 | C32: 4 | D32: =C32*B32 -> 1
A33: Does it avoid irrelevant and excessive information and is concise? (Length) | B33: 0.1 | C33: 3 | D33: =C33*B33 -> 0.3
B34: =SUM(B27:B33) -> 1 | D34: =SUM(D27:D33) -> 3.75
A36: deepseek-v3.2 | FI
A37: Metric | B37: Weight | C37: Score [1,5] | D37: Weighted Score
A38: Is the explanation technically correct and based on the information provided without distorting the diagnostic information? (Soundness) | B38: 0.25 | C38: 3 | D38: =C38*B38 -> 0.75
A39: Is the explanation readable, coherent and easy to understand for non-experts? (Fluency) | B39: 0.1 | C39: 4 | D39: =C39*B39 -> 0.4
A40: Is the available information used for the reasoning? (Performance/Feature Importance/Combination) (Completeness) | B40: 0.1 | C40: 3 | D40: =C40*B40 -> 0.3
A41: Does it answer why the specific device is behaving unusually or has a bad performance? (Completeness) | B41: 0.1 | C41: 3 | D41: =C41*B41 -> 0.3
A42: Does it provide actionable insights that support the decision making? (Completeness) | B42: 0.1 | C42: 4 | D42: =C42*B42 -> 0.4
A43: Is there a coherent argumentation and reasoning provided for the interpretation based on the information provided? (Context-Awareness) | B43: 0.25 | C43: 3 | D43: =C43*B43 -> 0.75
...

Sheet d131 #3
A1: Max Score: | B1: 5
F2: Weighted Score:
A3: gwen3.5 | FI | F3: =D12 -> 4.1
A4: Metric | B4: Weight | C4: Score [1,5] | D4: Weighted Score | F4: =D23 -> 4.3
A5: Is the explanation technically correct and based on the information provided without distorting the diagnostic information? (Soundness) | B5: 0.25 | C5: 4 | D5: =C5*B5 -> 1 | F5: =D34 -> 4.3
A6: Is the explanation readable, coherent and easy to understand for non-experts? (Fluency) | B6: 0.1 | C6: 5 | D6: =C6*B6 -> 0.5 | F6: =D45 -> 4.1
A7: Is the available information used for the reasoning? (Performance/Feature Importance/Combination) (Completeness) | B7: 0.1 | C7: 4 | D7: =C7*B7 -> 0.4 | F7: =D56 -> 4.2
A8: Does it answer why the specific device is behaving unusually or has a bad performance? (Completeness) | B8: 0.1 | C8: 4 | D8: =C8*B8 -> 0.4 | F8: =D67 -> 4.2
A9: Does it provide actionable insights that support the decision making? (Completeness) | B9: 0.1 | C9: 3 | D9: =C9*B9 -> 0.3 | F9: =D78 -> 3.4
A10: Is there a coherent argumentation and reasoning provided for the interpretation based on the information provided? (Context-Awareness) | B10: 0.25 | C10: 4 | D10: =C10*B10 -> 1 | F10: =D89 -> 3.85
A11: Does it avoid irrelevant and excessive information and is concise? (Length) | B11: 0.1 | C11: 5 | D11: =C11*B11 -> 0.5 | F11: =D100 -> 4.75
B12: =SUM(B5:B11) -> 1 | D12: =SUM(D5:D11) -> 4.1
A14: gwen3.5 | P
A15: Metric | B15: Weight | C15: Score [1,5] | D15: Weighted Score
A16: Is the explanation technically correct and based on the information provided without distorting the diagnostic information? (Soundness) | B16: 0.25 | C16: 4 | D16: =C16*B16 -> 1
A17: Is the explanation readable, coherent and easy to understand for non-experts? (Fluency) | B17: 0.1 | C17: 5 | D17: =C17*B17 -> 0.5
A18: Is the available information used for the reasoning? (Performance/Feature Importance/Combination) (Completeness) | B18: 0.1 | C18: 4 | D18: =C18*B18 -> 0.4
A19: Does it answer why the specific device is behaving unusually or has a bad performance? (Completeness) | B19: 0.1 | C19: 4 | D19: =C19*B19 -> 0.4
A20: Does it provide actionable insights that support the decision making? (Completeness) | B20: 0.1 | C20: 5 | D20: =C20*B20 -> 0.5
A21: Is there a coherent argumentation and reasoning provided for the interpretation based on the information provided? (Context-Awareness) | B21: 0.25 | C21: 4 | D21: =C21*B21 -> 1
A22: Does it avoid irrelevant and excessive information and is concise? (Length) | B22: 0.1 | C22: 5 | D22: =C22*B22 -> 0.5
B23: =SUM(B16:B22) -> 1 | D23: =SUM(D16:D22) -> 4.3
A25: gwen3.5 | FI + P
A26: Metric | B26: Weight | C26: Score [1,5] | D26: Weighted Score
A27: Is the explanation technically correct and based on the information provided without distorting the diagnostic information? (Soundness) | B27: 0.25 | C27: 4 | D27: =C27*B27 -> 1
A28: Is the explanation readable, coherent and easy to understand for non-experts? (Fluency) | B28: 0.1 | C28: 5 | D28: =C28*B28 -> 0.5
A29: Is the available information used for the reasoning? (Performance/Feature Importance/Combination) (Completeness) | B29: 0.1 | C29: 4 | D29: =C29*B29 -> 0.4
A30: Does it answer why the specific device is behaving unusually or has a bad performance? (Completeness) | B30: 0.1 | C30: 5 | D30: =C30*B30 -> 0.5
A31: Does it provide actionable insights that support the decision making? (Completeness) | B31: 0.1 | C31: 5 | D31: =C31*B31 -> 0.5
A32: Is there a coherent argumentation and reasoning provided for the interpretation based on the information provided? (Context-Awareness) | B32: 0.25 | C32: 4 | D32: =C32*B32 -> 1
A33: Does it avoid irrelevant and excessive information and is concise? (Length) | B33: 0.1 | C33: 4 | D33: =C33*B33 -> 0.4
B34: =SUM(B27:B33) -> 1 | D34: =SUM(D27:D33) -> 4.3
A36: deepseek-v3.2 | FI
A37: Metric | B37: Weight | C37: Score [1,5] | D37: Weighted Score
A38: Is the explanation technically correct and based on the information provided without distorting the diagnostic information? (Soundness) | B38: 0.25 | C38: 4 | D38: =C38*B38 -> 1
A39: Is the explanation readable, coherent and easy to understand for non-experts? (Fluency) | B39: 0.1 | C39: 5 | D39: =C39*B39 -> 0.5
A40: Is the available information used for the reasoning? (Performance/Feature Importance/Combination) (Completeness) | B40: 0.1 | C40: 4 | D40: =C40*B40 -> 0.4
A41: Does it answer why the specific device is behaving unusually or has a bad performance? (Completeness) | B41: 0.1 | C41: 4 | D41: =C41*B41 -> 0.4
A42: Does it provide actionable insights that support the decision making? (Completeness) | B42: 0.1 | C42: 4 | D42: =C42*B42 -> 0.4
A43: Is there a coherent argumentation and reasoning provided for the interpretation based on the information provided? (Context-Awareness) | B43: 0.25 | C43: 4 | D43: =C43*B43 -> 1
...

Sheet d393 #3
A1: Max Score: | B1: 5
F2: Weighted Score:
A3: gwen3.5 | FI | F3: =D12 -> 4.1
A4: Metric | B4: Weight | C4: Score [1,5] | D4: Weighted Score | F4: =D23 -> 4.2
A5: Is the explanation technically correct and based on the information provided without distorting the diagnostic information? (Soundness) | B5: 0.25 | C5: 4 | D5: =C5*B5 -> 1 | F5: =D34 -> 4.35
A6: Is the explanation readable, coherent and easy to understand for non-experts? (Fluency) | B6: 0.1 | C6: 5 | D6: =C6*B6 -> 0.5 | F6: =D45 -> 4.1
A7: Is the available information used for the reasoning? (Performance/Feature Importance/Combination) (Completeness) | B7: 0.1 | C7: 4 | D7: =C7*B7 -> 0.4 | F7: =D56 -> 3.3
A8: Does it answer why the specific device is behaving unusually or has a bad performance? (Completeness) | B8: 0.1 | C8: 4 | D8: =C8*B8 -> 0.4 | F8: =D67 -> 4.1
A9: Does it provide actionable insights that support the decision making? (Completeness) | B9: 0.1 | C9: 3 | D9: =C9*B9 -> 0.3 | F9: =D78 -> 3.85
A10: Is there a coherent argumentation and reasoning provided for the interpretation based on the information provided? (Context-Awareness) | B10: 0.25 | C10: 4 | D10: =C10*B10 -> 1 | F10: =D89 -> 3.55
A11: Does it avoid irrelevant and excessive information and is concise? (Length) | B11: 0.1 | C11: 5 | D11: =C11*B11 -> 0.5 | F11: =D100 -> 3.9
B12: =SUM(B5:B11) -> 1 | D12: =SUM(D5:D11) -> 4.1
A14: gwen3.5 | P
A15: Metric | B15: Weight | C15: Score [1,5] | D15: Weighted Score
A16: Is the explanation technically correct and based on the information provided without distorting the diagnostic information? (Soundness) | B16: 0.25 | C16: 4 | D16: =C16*B16 -> 1
A17: Is the explanation readable, coherent and easy to understand for non-experts? (Fluency) | B17: 0.1 | C17: 5 | D17: =C17*B17 -> 0.5
A18: Is the available information used for the reasoning? (Performance/Feature Importance/Combination) (Completeness) | B18: 0.1 | C18: 4 | D18: =C18*B18 -> 0.4
A19: Does it answer why the specific device is behaving unusually or has a bad performance? (Completeness) | B19: 0.1 | C19: 4 | D19: =C19*B19 -> 0.4
A20: Does it provide actionable insights that support the decision making? (Completeness) | B20: 0.1 | C20: 4 | D20: =C20*B20 -> 0.4
A21: Is there a coherent argumentation and reasoning provided for the interpretation based on the information provided? (Context-Awareness) | B21: 0.25 | C21: 4 | D21: =C21*B21 -> 1
A22: Does it avoid irrelevant and excessive information and is concise? (Length) | B22: 0.1 | C22: 5 | D22: =C22*B22 -> 0.5
B23: =SUM(B16:B22) -> 1 | D23: =SUM(D16:D22) -> 4.2
A25: gwen3.5 | FI + P
A26: Metric | B26: Weight | C26: Score [1,5] | D26: Weighted Score
A27: Is the explanation technically correct and based on the information provided without distorting the diagnostic information? (Soundness) | B27: 0.25 | C27: 4 | D27: =C27*B27 -> 1
A28: Is the explanation readable, coherent and easy to understand for non-experts? (Fluency) | B28: 0.1 | C28: 5 | D28: =C28*B28 -> 0.5
A29: Is the available information used for the reasoning? (Performance/Feature Importance/Combination) (Completeness) | B29: 0.1 | C29: 4 | D29: =C29*B29 -> 0.4
A30: Does it answer why the specific device is behaving unusually or has a bad performance? (Completeness) | B30: 0.1 | C30: 4 | D30: =C30*B30 -> 0.4
A31: Does it provide actionable insights that support the decision making? (Completeness) | B31: 0.1 | C31: 3 | D31: =C31*B31 -> 0.3
A32: Is there a coherent argumentation and reasoning provided for the interpretation based on the information provided? (Context-Awareness) | B32: 0.25 | C32: 5 | D32: =C32*B32 -> 1.25
A33: Does it avoid irrelevant and excessive information and is concise? (Length) | B33: 0.1 | C33: 5 | D33: =C33*B33 -> 0.5
B34: =SUM(B27:B33) -> 1 | D34: =SUM(D27:D33) -> 4.35
A36: deepseek-v3.2 | FI
A37: Metric | B37: Weight | C37: Score [1,5] | D37: Weighted Score
A38: Is the explanation technically correct and based on the information provided without distorting the diagnostic information? (Soundness) | B38: 0.25 | C38: 4 | D38: =C38*B38 -> 1
A39: Is the explanation readable, coherent and easy to understand for non-experts? (Fluency) | B39: 0.1 | C39: 5 | D39: =C39*B39 -> 0.5
A40: Is the available information used for the reasoning? (Performance/Feature Importance/Combination) (Completeness) | B40: 0.1 | C40: 4 | D40: =C40*B40 -> 0.4
A41: Does it answer why the specific device is behaving unusually or has a bad performance? (Completeness) | B41: 0.1 | C41: 4 | D41: =C41*B41 -> 0.4
A42: Does it provide actionable insights that support the decision making? (Completeness) | B42: 0.1 | C42: 4 | D42: =C42*B42 -> 0.4
A43: Is there a coherent argumentation and reasoning provided for the interpretation based on the information provided? (Context-Awareness) | B43: 0.25 | C43: 4 | D43: =C43*B43 -> 1
...

Sheet d1456 #3
A1: Max Score: | B1: 5
F2: Weighted Score:
A3: gwen3.5 | FI | F3: =D12 -> 4.55
A4: Metric | B4: Weight | C4: Score [1,5] | D4: Weighted Score | F4: =D23 -> 3.5
A5: Is the explanation technically correct and based on the information provided without distorting the diagnostic information? (Soundness) | B5: 0.25 | C5: 4 | D5: =C5*B5 -> 1 | F5: =D34 -> 3.75
A6: Is the explanation readable, coherent and easy to understand for non-experts? (Fluency) | B6: 0.1 | C6: 5 | D6: =C6*B6 -> 0.5 | F6: =D45 -> 4.1
