Workbook

Sheet Evaluation Table
D1: Experiment 1 (mainly num) | F1: Experiment 2 (mainly text) | J1: Experiment 3 (mainly text + other models) | N1: Experiment 4 (mainly visual) | R1: Experiment 5 (Combination) | V1: Experiment 6 (Combinaiton)
D2: d88 | E2: d131 | F2: d88 | G2: d131 | H2: d1383 | I2: d1456 | J2: d88 | K2: d131 | L2: d1383 | M2: d1456 | N2: d88 | O2: d131 | P2: d1383 | Q2: d1456 | R2: d88 | S2: d131 | T2: d1383 | U2: d1456 | V2: d88 | W2: d131 | X2: d1383 | Y2: d1456
A3: qwen3.5 | B3: WS | C3: FI | D3: ='d88 #1'!D14 -> 2.7 | E3: ='d131 #1'!D14 -> 2.5
C4: P | D4: ='d88 #1'!D27 -> 2.9 | E4: ='d131 #1'!D27 -> 2.75
C5: FI + P | D5: ='d88 #1'!D40 -> 2.9 | E5: ='d131 #1'!D40 -> 2.55
B6: AM | C6: FI
C7: P
C8: FI + P
B9: SA | C9: FI
C10: P
C11: FI + P
A12: deepseek-v3.2 | B12: WS | C12: FI | D12: ='d88 #1'!D53 -> 3.25 | E12: ='d131 #1'!D53 -> 3.25
C13: P | D13: ='d88 #1'!D66 -> 3 | E13: ='d131 #1'!D66 -> 3.15
C14: FI + P | D14: ='d88 #1'!D79 -> 3.1 | E14: ='d131 #1'!D79 -> 3.3
B15: AM | C15: FI
C16: P
C17: FI + P
B18: SA | C18: FI
C19: P
C20: FI + P
A21: kimi-k2.5 | B21: WS | C21: FI | D21: ='d88 #1'!D92 -> 3.1 | E21: ='d131 #1'!D92 -> 3
C22: P | D22: ='d88 #1'!D105 -> 3.1 | E22: ='d131 #1'!D105 -> 3.1
C23: FI + P | D23: ='d88 #1'!D118 -> 3.05 | E23: ='d131 #1'!D118 -> 3.1
B24: AM | C24: FI
C25: P
C26: FI + P
B27: SA | C27: FI
C28: P
C29: FI + P
A31: gwen3.5
A32: deepseek-v3.2
A33: kimi-k2.5
A35: FI
A36: P
A37: FI + P

Sheet d88 #1
A1: Max Score: | B1: =B5*5 + B6*5 +B7*5+B8*5+B9*5+B10*5+B11*5+B12*5+B13*5 -> 5
F2: Input Structure: | G2: Schema:
A3: gwen3.5 | FI | G3: {
A4: Metric | B4: Weight | C4: Score [1,5] | D4: Weighted Score | G4: "Device Information": {
A5: Does it answer the question of why this is an anomaly or performs bad? | B5: 0.15 | C5: 3 | D5: =C5*B5 -> 0.45 | G5: "tags": {
A6: Is all the available information used for the reasoning? (Performance/Feature Importance) | B6: 0.1 | C6: 2 | D6: =C6*B6 -> 0.2 | G6: "name": "ASHGABAT",
A7: Is there a coherent argumentation and reasoning provided for the interpretation? | B7: 0.1 | C7: 3 | D7: =C7*B7 -> 0.3 | G7: "state": "Not applicable",
A8: Is there a correct interpretation of relationships? | B8: 0.15 | C8: 2 | D8: =C8*B8 -> 0.3 | G8: "tz": "UTC+5",
A9: Is external or domain knowledge integrated into reasoning? | B9: 0.15 | C9: 2 | D9: =C9*B9 -> 0.3 | G9: "city": "Ashgabat",
A10: Does it provide a clear and concise explanation? (writing style) | B10: 0.05 | C10: 4 | D10: =C10*B10 -> 0.2 | G10: "urbanization": "unknown",
A11: Does it avoid irrelevant or excessive information? (information provided) | B11: 0.05 | C11: 4 | D11: =C11*B11 -> 0.2 | G11: "country": "Turkmenistan",
A12: Is it clear and easy to understand for non-experts? | B12: 0.1 | C12: 3 | D12: =C12*B12 -> 0.3 | G12: "station_id": "TXI0000UTAA",
A13: Does it help the decision-making and provide actionability? | B13: 0.15 | C13: 3 | D13: =C13*B13 -> 0.45
B14: =SUM(B5:B13) -> 1 | D14: =SUM(D5:D13) -> 2.7 | G14: "terrain": "hill"
G15: }
A16: gwen3.5 | P | G16: },
A17: Metric | B17: Weight | C17: Score [1,5] | D17: Weighted Score | G17: "Active Model Context": {
A18: Does it answer the question of why this is an anomaly or performs bad? | B18: 0.15 | C18: 3 | D18: =C18*B18 -> 0.45 | G18: "version": 16,
A19: Is all the available information used for the reasoning? (Performance/Feature Importance) | B19: 0.1 | C19: 3 | D19: =C19*B19 -> 0.3 | G19: "is_valid": 1,
A20: Is there a coherent argumentation and reasoning provided for the interpretation? | B20: 0.1 | C20: 3 | D20: =C20*B20 -> 0.3 | G20: "is_compatible": 1,
A21: Is there a correct interpretation of relationships? | B21: 0.15 | C21: 2 | D21: =C21*B21 -> 0.3 | G21: "model_age_days": 221,
A22: Is external or domain knowledge integrated into reasoning? | B22: 0.15 | C22: 2 | D22: =C22*B22 -> 0.3 | G22: "training_recency_bucket": "recent"
A23: Does it provide a clear and concise explanation? (writing style) | B23: 0.05 | C23: 4 | D23: =C23*B23 -> 0.2 | G23: },
A24: Does it avoid irrelevant or excessive information? (information provided) | B24: 0.05 | C24: 4 | D24: =C24*B24 -> 0.2 | G24: "Model Performance Context": {
A25: Is it clear and easy to understand for non-experts? | B25: 0.1 | C25: 4 | D25: =C25*B25 -> 0.4 | G25: "average metrics": {
A26: Does it help the decision-making and provide actionability? | B26: 0.15 | C26: 3 | D26: =C26*B26 -> 0.45 | G26: "MAE": 9.151254452191866,
B27: =SUM(B18:B26) -> 1 | D27: =SUM(D18:D26) -> 2.9 | G27: "RMSE": 0.35316544647018117,
G28: "MAPE": 9.989967272831844
A29: gwen3.5 | FI + P | G29: },
A30: Metric | B30: Weight | C30: Score [1,5] | D30: Weighted Score | G30: "overall_error_score": 7.133781451477988,
A31: Does it answer the question of why this is an anomaly or performs bad? | B31: 0.15 | C31: 3 | D31: =C31*B31 -> 0.45 | G31: "trend": "degrading",
A32: Is all the available information used for the reasoning? (Performance/Feature Importance) | B32: 0.1 | C32: 2 | D32: =C32*B32 -> 0.2 | G32: "worst_performance_error_score": 3.06753407135631,
A33: Is there a coherent argumentation and reasoning provided for the interpretation? | B33: 0.1 | C33: 3 | D33: =C33*B33 -> 0.3 | G33: "worst_time_stamp": "2025-01-30 11:11:29"
A34: Is there a correct interpretation of relationships? | B34: 0.15 | C34: 3 | D34: =C34*B34 -> 0.45 | G34: },
A35: Is external or domain knowledge integrated into reasoning? | B35: 0.15 | C35: 2 | D35: =C35*B35 -> 0.3 | G35: "Model Version History": {
A36: Does it provide a clear and concise explanation? (writing style) | B36: 0.05 | C36: 4 | D36: =C36*B36 -> 0.2 | G36: "versions_available": 15,
A37: Does it avoid irrelevant or excessive information? (information provided) | B37: 0.05 | C37: 3 | D37: =C37*B37 -> 0.15 | G37: "average_performance": {
A38: Is it clear and easy to understand for non-experts? | B38: 0.1 | C38: 4 | D38: =C38*B38 -> 0.4 | G38: "MAE": 7.670857318242391,
A39: Does it help the decision-making and provide actionability? | B39: 0.15 | C39: 3 | D39: =C39*B39 -> 0.45 | G39: "MAPE": 9.008195066452027,
B40: =SUM(B31:B39) -> 1 | D40: =SUM(D31:D39) -> 2.9 | G40: "RMSE": null
...

Sheet d131 #1
A1: Max Score: | B1: =B5*5 + B6*5 +B7*5+B8*5+B9*5+B10*5+B11*5+B12*5+B13*5 -> 5
F2: Input Structure: | G2: Schema:
A3: gwen3.5 | FI | G3: {
A4: Metric | B4: Weight | C4: Score [1,5] | D4: Weighted Score | G4: "Device Information": {
A5: Does it answer the question of why this is an anomaly or performs bad? | B5: 0.15 | C5: 2 | D5: =C5*B5 -> 0.3 | G5: "tags": {
A6: Is all the available information used for the reasoning? (Performance/Feature Importance) | B6: 0.1 | C6: 2 | D6: =C6*B6 -> 0.2 | G6: "terrain": "lowland",
A7: Is there a coherent argumentation and reasoning provided for the interpretation? | B7: 0.1 | C7: 2 | D7: =C7*B7 -> 0.2 | G7: "name": "OGOKI POST A",
A8: Is there a correct interpretation of relationships? | B8: 0.15 | C8: 2 | D8: =C8*B8 -> 0.3 | G8: "tz": "UTC-5",
A9: Is external or domain knowledge integrated into reasoning? | B9: 0.15 | C9: 2 | D9: =C9*B9 -> 0.3 | G9: "country": "Canada",
A10: Does it provide a clear and concise explanation? (writing style) | B10: 0.05 | C10: 4 | D10: =C10*B10 -> 0.2 | G10: "station_id": "CAN06075786",
A11: Does it avoid irrelevant or excessive information? (information provided) | B11: 0.05 | C11: 3 | D11: =C11*B11 -> 0.15 | G11: "urbanization": "rural",
A12: Is it clear and easy to understand for non-experts? | B12: 0.1 | C12: 4 | D12: =C12*B12 -> 0.4 | G12: "city": "Greenstone",
A13: Does it help the decision-making and provide actionability? | B13: 0.15 | C13: 3 | D13: =C13*B13 -> 0.45 | G13: "state": "Ontario"
B14: =SUM(B5:B13) -> 1 | D14: =SUM(D5:D13) -> 2.5 | G14: }
G15: },
A16: gwen3.5 | P | G16: "Active Model Context": {
A17: Metric | B17: Weight | C17: Score [1,5] | D17: Weighted Score | G17: "version": 8,
A18: Does it answer the question of why this is an anomaly or performs bad? | B18: 0.15 | C18: 3 | D18: =C18*B18 -> 0.45 | G18: "is_valid": 1,
A19: Is all the available information used for the reasoning? (Performance/Feature Importance) | B19: 0.1 | C19: 3 | D19: =C19*B19 -> 0.3 | G19: "is_compatible": 1,
A20: Is there a coherent argumentation and reasoning provided for the interpretation? | B20: 0.1 | C20: 2 | D20: =C20*B20 -> 0.2 | G20: "model_age_days": 1547,
A21: Is there a correct interpretation of relationships? | B21: 0.15 | C21: 2 | D21: =C21*B21 -> 0.3 | G21: "training_recency_bucket": "outdated"
A22: Is external or domain knowledge integrated into reasoning? | B22: 0.15 | C22: 2 | D22: =C22*B22 -> 0.3 | G22: },
A23: Does it provide a clear and concise explanation? (writing style) | B23: 0.05 | C23: 4 | D23: =C23*B23 -> 0.2 | G23: "Model Performance Context": {
A24: Does it avoid irrelevant or excessive information? (information provided) | B24: 0.05 | C24: 3 | D24: =C24*B24 -> 0.15 | G24: "average metrics": {
A25: Is it clear and easy to understand for non-experts? | B25: 0.1 | C25: 4 | D25: =C25*B25 -> 0.4 | G25: "MAE": 16.670150637626648,
A26: Does it help the decision-making and provide actionability? | B26: 0.15 | C26: 3 | D26: =C26*B26 -> 0.45 | G26: "RMSE": 4.384457421302796,
B27: =SUM(B18:B26) -> 1 | D27: =SUM(D18:D26) -> 2.75 | G27: "MAPE": 17.724907338619232
G28: },
A29: gwen3.5 | FI + P | G29: "overall_error_score": 12.977009995000667,
A30: Metric | B30: Weight | C30: Score [1,5] | D30: Weighted Score | G30: "trend": "degrading",
A31: Does it answer the question of why this is an anomaly or performs bad? | B31: 0.15 | C31: 2 | D31: =C31*B31 -> 0.3 | G31: "worst_performance_error_score": 8.035996518007464,
A32: Is all the available information used for the reasoning? (Performance/Feature Importance) | B32: 0.1 | C32: 2 | D32: =C32*B32 -> 0.2 | G32: "worst_time_stamp": "2025-01-30 11:10:05"
A33: Is there a coherent argumentation and reasoning provided for the interpretation? | B33: 0.1 | C33: 3 | D33: =C33*B33 -> 0.3 | G33: },
A34: Is there a correct interpretation of relationships? | B34: 0.15 | C34: 3 | D34: =C34*B34 -> 0.45 | G34: "Model Version History": {
A35: Is external or domain knowledge integrated into reasoning? | B35: 0.15 | C35: 2 | D35: =C35*B35 -> 0.3 | G35: "versions_available": 7,
A36: Does it provide a clear and concise explanation? (writing style) | B36: 0.05 | C36: 4 | D36: =C36*B36 -> 0.2 | G36: "average_performance": {
A37: Does it avoid irrelevant or excessive information? (information provided) | B37: 0.05 | C37: 4 | D37: =C37*B37 -> 0.2 | G37: "MAE": 9.934088706970215,
A38: Is it clear and easy to understand for non-experts? | B38: 0.1 | C38: 3 | D38: =C38*B38 -> 0.3 | G38: "MAPE": 11.332808494567871,
A39: Does it help the decision-making and provide actionability? | B39: 0.15 | C39: 2 | D39: =C39*B39 -> 0.3 | G39: "RMSE": null
B40: =SUM(B31:B39) -> 1 | D40: =SUM(D31:D39) -> 2.55 | G40: }
...

Sheet d88 #2
A1: Max Score: | B1: =B5*5 + B6*5 +B7*5+B8*5+B9*5+B10*5+B11*5+B12*5+B13*5 -> 5
F2: Input Structure:
A3: gwen3.5 | FI
A4: Metric | B4: Weight | C4: Score [1,5] | D4: Weighted Score
A5: Does it answer the question of why this is an anomaly or performs bad? | B5: 0.15 | C5: 4 | D5: =C5*B5 -> 0.6
A6: Is all the available information used for the reasoning? (Performance/Feature Importance) | B6: 0.1 | C6: 4 | D6: =C6*B6 -> 0.4
A7: Is there a coherent argumentation and reasoning provided for the interpretation? | B7: 0.1 | C7: 3 | D7: =C7*B7 -> 0.3
A8: Is there a correct interpretation of relationships? | B8: 0.15 | C8: 2 | D8: =C8*B8 -> 0.3
A9: Is external or domain knowledge integrated into reasoning? | B9: 0.15 | C9: 3 | D9: =C9*B9 -> 0.45
A10: Does it provide a clear and concise explanation? (writing style) | B10: 0.05 | C10: 2 | D10: =C10*B10 -> 0.1
A11: Does it avoid irrelevant or excessive information? (information provided) | B11: 0.05 | C11: 2 | D11: =C11*B11 -> 0.1
A12: Is it clear and easy to understand for non-experts? | B12: 0.1 | C12: 4 | D12: =C12*B12 -> 0.4
A13: Does it help the decision-making and provide actionability? | B13: 0.15 | C13: 4 | D13: =C13*B13 -> 0.6
B14: =SUM(B5:B13) -> 1 | D14: =SUM(D5:D13) -> 3.25
A16: gwen3.5 | P
A17: Metric | B17: Weight | C17: Score [1,5] | D17: Weighted Score
A18: Does it answer the question of why this is an anomaly or performs bad? | B18: 0.15 | C18: 4 | D18: =C18*B18 -> 0.6
A19: Is all the available information used for the reasoning? (Performance/Feature Importance) | B19: 0.1 | C19: 4 | D19: =C19*B19 -> 0.4
A20: Is there a coherent argumentation and reasoning provided for the interpretation? | B20: 0.1 | C20: 3 | D20: =C20*B20 -> 0.3
A21: Is there a correct interpretation of relationships? | B21: 0.15 | C21: 2 | D21: =C21*B21 -> 0.3
A22: Is external or domain knowledge integrated into reasoning? | B22: 0.15 | C22: 3 | D22: =C22*B22 -> 0.45
A23: Does it provide a clear and concise explanation? (writing style) | B23: 0.05 | C23: 2 | D23: =C23*B23 -> 0.1
A24: Does it avoid irrelevant or excessive information? (information provided) | B24: 0.05 | C24: 2 | D24: =C24*B24 -> 0.1
A25: Is it clear and easy to understand for non-experts? | B25: 0.1 | C25: 4 | D25: =C25*B25 -> 0.4
A26: Does it help the decision-making and provide actionability? | B26: 0.15 | C26: 4 | D26: =C26*B26 -> 0.6
B27: =SUM(B18:B26) -> 1 | D27: =SUM(D18:D26) -> 3.25
A29: gwen3.5 | FI + P
A30: Metric | B30: Weight | C30: Score [1,5] | D30: Weighted Score
A31: Does it answer the question of why this is an anomaly or performs bad? | B31: 0.15 | C31: 4 | D31: =C31*B31 -> 0.6
A32: Is all the available information used for the reasoning? (Performance/Feature Importance) | B32: 0.1 | C32: 4 | D32: =C32*B32 -> 0.4
A33: Is there a coherent argumentation and reasoning provided for the interpretation? | B33: 0.1 | C33: 3 | D33: =C33*B33 -> 0.3
A34: Is there a correct interpretation of relationships? | B34: 0.15 | C34: 2 | D34: =C34*B34 -> 0.3
A35: Is external or domain knowledge integrated into reasoning? | B35: 0.15 | C35: 3 | D35: =C35*B35 -> 0.45
A36: Does it provide a clear and concise explanation? (writing style) | B36: 0.05 | C36: 2 | D36: =C36*B36 -> 0.1
A37: Does it avoid irrelevant or excessive information? (information provided) | B37: 0.05 | C37: 2 | D37: =C37*B37 -> 0.1
A38: Is it clear and easy to understand for non-experts? | B38: 0.1 | C38: 4 | D38: =C38*B38 -> 0.4
A39: Does it help the decision-making and provide actionability? | B39: 0.15 | C39: 4 | D39: =C39*B39 -> 0.6
B40: =SUM(B31:B39) -> 1 | D40: =SUM(D31:D39) -> 3.25
A42: deepseek-v3.2 | FI
A43: Metric | B43: Weight | C43: Score [1,5] | D43: Weighted Score
...

Sheet d131 #2
A1: Max Score: | B1: =B5*5 + B6*5 +B7*5+B8*5+B9*5+B10*5+B11*5+B12*5+B13*5 -> 5
F2: Input Structure:
A3: gwen3.5 | FI
A4: Metric | B4: Weight | C4: Score [1,5] | D4: Weighted Score
A5: Does it answer the question of why this is an anomaly or performs bad? | B5: 0.15 | C5: 4 | D5: =C5*B5 -> 0.6
A6: Is all the available information used for the reasoning? (Performance/Feature Importance) | B6: 0.1 | C6: 4 | D6: =C6*B6 -> 0.4
A7: Is there a coherent argumentation and reasoning provided for the interpretation? | B7: 0.1 | C7: 3 | D7: =C7*B7 -> 0.3
A8: Is there a correct interpretation of relationships? | B8: 0.15 | C8: 2 | D8: =C8*B8 -> 0.3
A9: Is external or domain knowledge integrated into reasoning? | B9: 0.15 | C9: 3 | D9: =C9*B9 -> 0.45
A10: Does it provide a clear and concise explanation? (writing style) | B10: 0.05 | C10: 2 | D10: =C10*B10 -> 0.1
A11: Does it avoid irrelevant or excessive information? (information provided) | B11: 0.05 | C11: 2 | D11: =C11*B11 -> 0.1
A12: Is it clear and easy to understand for non-experts? | B12: 0.1 | C12: 4 | D12: =C12*B12 -> 0.4
A13: Does it help the decision-making and provide actionability? | B13: 0.15 | C13: 4 | D13: =C13*B13 -> 0.6
B14: =SUM(B5:B13) -> 1 | D14: =SUM(D5:D13) -> 3.25
A16: gwen3.5 | P
A17: Metric | B17: Weight | C17: Score [1,5] | D17: Weighted Score
A18: Does it answer the question of why this is an anomaly or performs bad? | B18: 0.15 | C18: 4 | D18: =C18*B18 -> 0.6
A19: Is all the available information used for the reasoning? (Performance/Feature Importance) | B19: 0.1 | C19: 4 | D19: =C19*B19 -> 0.4
A20: Is there a coherent argumentation and reasoning provided for the interpretation? | B20: 0.1 | C20: 3 | D20: =C20*B20 -> 0.3
A21: Is there a correct interpretation of relationships? | B21: 0.15 | C21: 2 | D21: =C21*B21 -> 0.3
A22: Is external or domain knowledge integrated into reasoning? | B22: 0.15 | C22: 3 | D22: =C22*B22 -> 0.45
A23: Does it provide a clear and concise explanation? (writing style) | B23: 0.05 | C23: 2 | D23: =C23*B23 -> 0.1
A24: Does it avoid irrelevant or excessive information? (information provided) | B24: 0.05 | C24: 2 | D24: =C24*B24 -> 0.1
A25: Is it clear and easy to understand for non-experts? | B25: 0.1 | C25: 4 | D25: =C25*B25 -> 0.4
A26: Does it help the decision-making and provide actionability? | B26: 0.15 | C26: 4 | D26: =C26*B26 -> 0.6
B27: =SUM(B18:B26) -> 1 | D27: =SUM(D18:D26) -> 3.25
A29: gwen3.5 | FI + P
A30: Metric | B30: Weight | C30: Score [1,5] | D30: Weighted Score
A31: Does it answer the question of why this is an anomaly or performs bad? | B31: 0.15 | C31: 4 | D31: =C31*B31 -> 0.6
A32: Is all the available information used for the reasoning? (Performance/Feature Importance) | B32: 0.1 | C32: 4 | D32: =C32*B32 -> 0.4
A33: Is there a coherent argumentation and reasoning provided for the interpretation? | B33: 0.1 | C33: 3 | D33: =C33*B33 -> 0.3
A34: Is there a correct interpretation of relationships? | B34: 0.15 | C34: 2 | D34: =C34*B34 -> 0.3
A35: Is external or domain knowledge integrated into reasoning? | B35: 0.15 | C35: 3 | D35: =C35*B35 -> 0.45
A36: Does it provide a clear and concise explanation? (writing style) | B36: 0.05 | C36: 2 | D36: =C36*B36 -> 0.1
A37: Does it avoid irrelevant or excessive information? (information provided) | B37: 0.05 | C37: 2 | D37: =C37*B37 -> 0.1
A38: Is it clear and easy to understand for non-experts? | B38: 0.1 | C38: 4 | D38: =C38*B38 -> 0.4
A39: Does it help the decision-making and provide actionability? | B39: 0.15 | C39: 4 | D39: =C39*B39 -> 0.6
B40: =SUM(B31:B39) -> 1 | D40: =SUM(D31:D39) -> 3.25
A42: deepseek-v3.2 | FI
A43: Metric | B43: Weight | C43: Score [1,5] | D43: Weighted Score
...

Sheet d1383 #2
A1: Max Score: | B1: =B5*5 + B6*5 +B7*5+B8*5+B9*5+B10*5+B11*5+B12*5+B13*5 -> 5
F2: Input Structure:
A3: gwen3.5 | FI
A4: Metric | B4: Weight | C4: Score [1,5] | D4: Weighted Score
A5: Does it answer the question of why this is an anomaly or performs bad? | B5: 0.15 | C5: 4 | D5: =C5*B5 -> 0.6
A6: Is all the available information used for the reasoning? (Performance/Feature Importance) | B6: 0.1 | C6: 4 | D6: =C6*B6 -> 0.4
A7: Is there a coherent argumentation and reasoning provided for the interpretation? | B7: 0.1 | C7: 3 | D7: =C7*B7 -> 0.3
A8: Is there a correct interpretation of relationships? | B8: 0.15 | C8: 2 | D8: =C8*B8 -> 0.3
A9: Is external or domain knowledge integrated into reasoning? | B9: 0.15 | C9: 3 | D9: =C9*B9 -> 0.45
A10: Does it provide a clear and concise explanation? (writing style) | B10: 0.05 | C10: 2 | D10: =C10*B10 -> 0.1
A11: Does it avoid irrelevant or excessive information? (information provided) | B11: 0.05 | C11: 2 | D11: =C11*B11 -> 0.1
A12: Is it clear and easy to understand for non-experts? | B12: 0.1 | C12: 4 | D12: =C12*B12 -> 0.4
A13: Does it help the decision-making and provide actionability? | B13: 0.15 | C13: 4 | D13: =C13*B13 -> 0.6
B14: =SUM(B5:B13) -> 1 | D14: =SUM(D5:D13) -> 3.25
A16: gwen3.5 | P
A17: Metric | B17: Weight | C17: Score [1,5] | D17: Weighted Score
A18: Does it answer the question of why this is an anomaly or performs bad? | B18: 0.15 | C18: 4 | D18: =C18*B18 -> 0.6
A19: Is all the available information used for the reasoning? (Performance/Feature Importance) | B19: 0.1 | C19: 4 | D19: =C19*B19 -> 0.4
A20: Is there a coherent argumentation and reasoning provided for the interpretation? | B20: 0.1 | C20: 3 | D20: =C20*B20 -> 0.3
A21: Is there a correct interpretation of relationships? | B21: 0.15 | C21: 2 | D21: =C21*B21 -> 0.3
A22: Is external or domain knowledge integrated into reasoning? | B22: 0.15 | C22: 3 | D22: =C22*B22 -> 0.45
A23: Does it provide a clear and concise explanation? (writing style) | B23: 0.05 | C23: 2 | D23: =C23*B23 -> 0.1
A24: Does it avoid irrelevant or excessive information? (information provided) | B24: 0.05 | C24: 2 | D24: =C24*B24 -> 0.1
A25: Is it clear and easy to understand for non-experts? | B25: 0.1 | C25: 4 | D25: =C25*B25 -> 0.4
A26: Does it help the decision-making and provide actionability? | B26: 0.15 | C26: 4 | D26: =C26*B26 -> 0.6
B27: =SUM(B18:B26) -> 1 | D27: =SUM(D18:D26) -> 3.25
A29: gwen3.5 | FI + P
A30: Metric | B30: Weight | C30: Score [1,5] | D30: Weighted Score
A31: Does it answer the question of why this is an anomaly or performs bad? | B31: 0.15 | C31: 4 | D31: =C31*B31 -> 0.6
A32: Is all the available information used for the reasoning? (Performance/Feature Importance) | B32: 0.1 | C32: 4 | D32: =C32*B32 -> 0.4
A33: Is there a coherent argumentation and reasoning provided for the interpretation? | B33: 0.1 | C33: 3 | D33: =C33*B33 -> 0.3
A34: Is there a correct interpretation of relationships? | B34: 0.15 | C34: 2 | D34: =C34*B34 -> 0.3
A35: Is external or domain knowledge integrated into reasoning? | B35: 0.15 | C35: 3 | D35: =C35*B35 -> 0.45
A36: Does it provide a clear and concise explanation? (writing style) | B36: 0.05 | C36: 2 | D36: =C36*B36 -> 0.1
A37: Does it avoid irrelevant or excessive information? (information provided) | B37: 0.05 | C37: 2 | D37: =C37*B37 -> 0.1
A38: Is it clear and easy to understand for non-experts? | B38: 0.1 | C38: 4 | D38: =C38*B38 -> 0.4
A39: Does it help the decision-making and provide actionability? | B39: 0.15 | C39: 4 | D39: =C39*B39 -> 0.6
B40: =SUM(B31:B39) -> 1 | D40: =SUM(D31:D39) -> 3.25
A42: deepseek-v3.2 | FI
A43: Metric | B43: Weight | C43: Score [1,5] | D43: Weighted Score
...

Sheet d1456 #2
A1: Max Score: | B1: =B5*5 + B6*5 +B7*5+B8*5+B9*5+B10*5+B11*5+B12*5+B13*5 -> 5
F2: Input Structure:
A3: gwen3.5 | FI
A4: Metric | B4: Weight | C4: Score [1,5] | D4: Weighted Score
A5: Does it answer the question of why this is an anomaly or performs bad? | B5: 0.15 | C5: 4 | D5: =C5*B5 -> 0.6
A6: Is all the available information used for the reasoning? (Performance/Feature Importance) | B6: 0.1 | C6: 4 | D6: =C6*B6 -> 0.4
A7: Is there a coherent argumentation and reasoning provided for the interpretation? | B7: 0.1 | C7: 3 | D7: =C7*B7 -> 0.3
A8: Is there a correct interpretation of relationships? | B8: 0.15 | C8: 2 | D8: =C8*B8 -> 0.3
A9: Is external or domain knowledge integrated into reasoning? | B9: 0.15 | C9: 3 | D9: =C9*B9 -> 0.45
A10: Does it provide a clear and concise explanation? (writing style) | B10: 0.05 | C10: 2 | D10: =C10*B10 -> 0.1
A11: Does it avoid irrelevant or excessive information? (information provided) | B11: 0.05 | C11: 2 | D11: =C11*B11 -> 0.1
A12: Is it clear and easy to understand for non-experts? | B12: 0.1 | C12: 4 | D12: =C12*B12 -> 0.4
A13: Does it help the decision-making and provide actionability? | B13: 0.15 | C13: 4 | D13: =C13*B13 -> 0.6
B14: =SUM(B5:B13) -> 1 | D14: =SUM(D5:D13) -> 3.25
A16: gwen3.5 | P
A17: Metric | B17: Weight | C17: Score [1,5] | D17: Weighted Score
A18: Does it answer the question of why this is an anomaly or performs bad? | B18: 0.15 | C18: 4 | D18: =C18*B18 -> 0.6
A19: Is all the available information used for the reasoning? (Performance/Feature Importance) | B19: 0.1 | C19: 4 | D19: =C19*B19 -> 0.4
A20: Is there a coherent argumentation and reasoning provided for the interpretation? | B20: 0.1 | C20: 3 | D20: =C20*B20 -> 0.3
A21: Is there a correct interpretation of relationships? | B21: 0.15 | C21: 2 | D21: =C21*B21 -> 0.3
A22: Is external or domain knowledge integrated into reasoning? | B22: 0.15 | C22: 3 | D22: =C22*B22 -> 0.45
A23: Does it provide a clear and concise explanation? (writing style) | B23: 0.05 | C23: 2 | D23: =C23*B23 -> 0.1
A24: Does it avoid irrelevant or excessive information? (information provided) | B24: 0.05 | C24: 2 | D24: =C24*B24 -> 0.1
A25: Is it clear and easy to understand for non-experts? | B25: 0.1 | C25: 4 | D25: =C25*B25 -> 0.4
A26: Does it help the decision-making and provide actionability? | B26: 0.15 | C26: 4 | D26: =C26*B26 -> 0.6
B27: =SUM(B18:B26) -> 1 | D27: =SUM(D18:D26) -> 3.25
A29: gwen3.5 | FI + P
A30: Metric | B30: Weight | C30: Score [1,5] | D30: Weighted Score
A31: Does it answer the question of why this is an anomaly or performs bad? | B31: 0.15 | C31: 4 | D31: =C31*B31 -> 0.6
A32: Is all the available information used for the reasoning? (Performance/Feature Importance) | B32: 0.1 | C32: 4 | D32: =C32*B32 -> 0.4
A33: Is there a coherent argumentation and reasoning provided for the interpretation? | B33: 0.1 | C33: 3 | D33: =C33*B33 -> 0.3
A34: Is there a correct interpretation of relationships? | B34: 0.15 | C34: 2 | D34: =C34*B34 -> 0.3
A35: Is external or domain knowledge integrated into reasoning? | B35: 0.15 | C35: 3 | D35: =C35*B35 -> 0.45
A36: Does it provide a clear and concise explanation? (writing style) | B36: 0.05 | C36: 2 | D36: =C36*B36 -> 0.1
A37: Does it avoid irrelevant or excessive information? (information provided) | B37: 0.05 | C37: 2 | D37: =C37*B37 -> 0.1
A38: Is it clear and easy to understand for non-experts? | B38: 0.1 | C38: 4 | D38: =C38*B38 -> 0.4
A39: Does it help the decision-making and provide actionability? | B39: 0.15 | C39: 4 | D39: =C39*B39 -> 0.6
B40: =SUM(B31:B39) -> 1 | D40: =SUM(D31:D39) -> 3.25
A42: deepseek-v3.2 | FI
A43: Metric | B43: Weight | C43: Score [1,5] | D43: Weighted Score
...
